2025-10-26 23:21:28,240 - configstream.geoip - INFO - [geoip.py:39] - GeoIP not configured (MAXMIND_LICENSE_KEY not set); skipping.
2025-10-26 23:21:28,252 - configstream.geoip - INFO - [geoip.py:39] - GeoIP not configured (MAXMIND_LICENSE_KEY not set); skipping.
2025-10-26 23:21:28,314 - configstream.geoip - INFO - [geoip.py:39] - GeoIP not configured (MAXMIND_LICENSE_KEY not set); skipping.
2025-10-26 23:21:28,405 - configstream.fetcher - INFO - [fetcher.py:270] - Successfully fetched 4 configs from http://127.0.0.1:39313/proxies (HTTP/1.1, Status: 200, Time: 0.01s)
2025-10-26 23:21:28,448 - configstream.fetcher - WARNING - [fetcher.py:318] - HTTP error fetching http://127.0.0.1:36511/flaky: Server error: 500
2025-10-26 23:21:28,558 - configstream.fetcher - WARNING - [fetcher.py:318] - HTTP error fetching http://127.0.0.1:36511/flaky: Server error: 500
2025-10-26 23:21:28,987 - configstream.fetcher - INFO - [fetcher.py:270] - Successfully fetched 1 configs from http://127.0.0.1:36511/flaky (HTTP/1.1, Status: 200, Time: 0.00s)
2025-10-26 23:21:30,002 - configstream.fetcher - WARNING - [fetcher.py:300] - Timeout fetching http://127.0.0.1:33503/slow (attempt 1/1)
2025-10-26 23:21:30,011 - configstream.fetcher - ERROR - [fetcher.py:345] - Failed to fetch http://127.0.0.1:33503/slow after 1 attempts. Last error: Timeout after 1 seconds
2025-10-26 23:21:34,017 - configstream.fetcher - WARNING - [fetcher.py:287] - Rate limit hit for http://127.0.0.1:46201/limited (host: 127.0.0.1:46201); retrying in 60.3s (attempt 1/1)
2025-10-26 23:22:34,391 - configstream.fetcher - ERROR - [fetcher.py:345] - Failed to fetch http://127.0.0.1:46201/limited after 1 attempts. Last error: Rate limited. Retry after 60.0 seconds
2025-10-26 23:22:34,408 - configstream.fetcher - INFO - [fetcher.py:270] - Successfully fetched 0 configs from http://127.0.0.1:45201/empty (HTTP/1.1, Status: 200, Time: 0.00s)
2025-10-26 23:22:34,424 - configstream.fetcher - WARNING - [fetcher.py:234] - Unexpected content type for http://127.0.0.1:39071/html: text/html; charset=utf-8
2025-10-26 23:22:34,426 - configstream.fetcher - INFO - [fetcher.py:270] - Successfully fetched 0 configs from http://127.0.0.1:39071/html (HTTP/1.1, Status: 200, Time: 0.00s)
2025-10-26 23:22:34,443 - configstream.fetcher - INFO - [fetcher.py:270] - Successfully fetched 1 configs from http://127.0.0.1:38957/redirect (HTTP/1.1, Status: 200, Time: 0.01s)
2025-10-26 23:22:36,123 - httpx - INFO - [_client.py:1740] - HTTP Request: GET http://127.0.0.1:34991/source3 "HTTP/1.1 500 Internal Server Error"
2025-10-26 23:22:36,132 - configstream.fetcher - WARNING - [fetcher.py:318] - HTTP error fetching http://127.0.0.1:34991/source3: Server error: 500
2025-10-26 23:22:36,136 - httpx - INFO - [_client.py:1740] - HTTP Request: GET http://127.0.0.1:34991/source2 "HTTP/1.1 200 OK"
2025-10-26 23:22:36,139 - configstream.fetcher - INFO - [fetcher.py:270] - Successfully fetched 1 configs from http://127.0.0.1:34991/source2 (HTTP/HTTP/1.1, Status: 200, Time: 0.04s)
2025-10-26 23:22:36,144 - httpx - INFO - [_client.py:1740] - HTTP Request: GET http://127.0.0.1:34991/source1 "HTTP/1.1 200 OK"
2025-10-26 23:22:36,147 - configstream.fetcher - INFO - [fetcher.py:270] - Successfully fetched 1 configs from http://127.0.0.1:34991/source1 (HTTP/HTTP/1.1, Status: 200, Time: 0.03s)
2025-10-26 23:22:37,411 - httpx - INFO - [_client.py:1740] - HTTP Request: GET http://127.0.0.1:34991/source3 "HTTP/1.1 500 Internal Server Error"
2025-10-26 23:22:37,414 - configstream.fetcher - WARNING - [fetcher.py:318] - HTTP error fetching http://127.0.0.1:34991/source3: Server error: 500
2025-10-26 23:22:39,605 - httpx - INFO - [_client.py:1740] - HTTP Request: GET http://127.0.0.1:34991/source3 "HTTP/1.1 500 Internal Server Error"
2025-10-26 23:22:39,608 - configstream.fetcher - WARNING - [fetcher.py:318] - HTTP error fetching http://127.0.0.1:34991/source3: Server error: 500
2025-10-26 23:22:39,610 - configstream.fetcher - ERROR - [fetcher.py:345] - Failed to fetch http://127.0.0.1:34991/source3 after 3 attempts. Last error: Server error: 500
2025-10-26 23:22:39,622 - configstream.fetcher - INFO - [fetcher.py:484] - Fetch complete: 2/3 sources successful (0 not modified), 2 total configs collected
2025-10-26 23:22:39,634 - configstream.fetcher - ERROR - [fetcher.py:115] - URL validation failed for not-a-url: Invalid URL format: not-a-url
2025-10-26 23:22:39,636 - configstream.fetcher - ERROR - [fetcher.py:115] - URL validation failed for http://: Invalid URL format: http://
2025-10-26 23:22:39,638 - configstream.fetcher - ERROR - [fetcher.py:115] - URL validation failed for ://missing-scheme: Invalid URL format: ://missing-scheme
2025-10-26 23:22:39,639 - configstream.fetcher - ERROR - [fetcher.py:115] - URL validation failed for http://[invalid: Invalid IPv6 URL
2025-10-26 23:22:39,648 - configstream.fetcher - WARNING - [fetcher.py:327] - HTTP error fetching http://test.com: Connection refused
2025-10-26 23:22:40,747 - configstream.fetcher - WARNING - [fetcher.py:327] - HTTP error fetching http://test.com: Connection refused
2025-10-26 23:22:43,043 - configstream.fetcher - WARNING - [fetcher.py:327] - HTTP error fetching http://test.com: Connection refused
2025-10-26 23:22:43,046 - configstream.fetcher - ERROR - [fetcher.py:345] - Failed to fetch http://test.com after 3 attempts. Last error: HTTP error: Connection refused
2025-10-26 23:22:43,236 - httpx - INFO - [_client.py:1740] - HTTP Request: GET http://127.0.0.1:38697/slow "HTTP/1.1 200 OK"
2025-10-26 23:22:43,239 - configstream.fetcher - INFO - [fetcher.py:270] - Successfully fetched 1 configs from http://127.0.0.1:38697/slow (HTTP/HTTP/1.1, Status: 200, Time: 0.11s)
2025-10-26 23:22:43,257 - httpx - INFO - [_client.py:1740] - HTTP Request: GET http://127.0.0.1:38697/slow "HTTP/1.1 200 OK"
2025-10-26 23:22:43,261 - configstream.fetcher - INFO - [fetcher.py:270] - Successfully fetched 1 configs from http://127.0.0.1:38697/slow (HTTP/HTTP/1.1, Status: 200, Time: 0.11s)
2025-10-26 23:22:43,277 - httpx - INFO - [_client.py:1740] - HTTP Request: GET http://127.0.0.1:38697/slow "HTTP/1.1 200 OK"
2025-10-26 23:22:43,281 - configstream.fetcher - INFO - [fetcher.py:270] - Successfully fetched 1 configs from http://127.0.0.1:38697/slow (HTTP/HTTP/1.1, Status: 200, Time: 0.11s)
2025-10-26 23:22:43,296 - httpx - INFO - [_client.py:1740] - HTTP Request: GET http://127.0.0.1:38697/slow "HTTP/1.1 200 OK"
2025-10-26 23:22:43,299 - configstream.fetcher - INFO - [fetcher.py:270] - Successfully fetched 1 configs from http://127.0.0.1:38697/slow (HTTP/HTTP/1.1, Status: 200, Time: 0.11s)
2025-10-26 23:22:43,316 - httpx - INFO - [_client.py:1740] - HTTP Request: GET http://127.0.0.1:38697/slow "HTTP/1.1 200 OK"
2025-10-26 23:22:43,319 - configstream.fetcher - INFO - [fetcher.py:270] - Successfully fetched 1 configs from http://127.0.0.1:38697/slow (HTTP/HTTP/1.1, Status: 200, Time: 0.11s)
2025-10-26 23:22:43,337 - httpx - INFO - [_client.py:1740] - HTTP Request: GET http://127.0.0.1:38697/slow "HTTP/1.1 200 OK"
2025-10-26 23:22:43,341 - configstream.fetcher - INFO - [fetcher.py:270] - Successfully fetched 1 configs from http://127.0.0.1:38697/slow (HTTP/HTTP/1.1, Status: 200, Time: 0.11s)
2025-10-26 23:22:43,352 - httpx - INFO - [_client.py:1740] - HTTP Request: GET http://127.0.0.1:38697/slow "HTTP/1.1 200 OK"
2025-10-26 23:22:43,355 - configstream.fetcher - INFO - [fetcher.py:270] - Successfully fetched 1 configs from http://127.0.0.1:38697/slow (HTTP/HTTP/1.1, Status: 200, Time: 0.11s)
2025-10-26 23:22:43,373 - httpx - INFO - [_client.py:1740] - HTTP Request: GET http://127.0.0.1:38697/slow "HTTP/1.1 200 OK"
2025-10-26 23:22:43,376 - configstream.fetcher - INFO - [fetcher.py:270] - Successfully fetched 1 configs from http://127.0.0.1:38697/slow (HTTP/HTTP/1.1, Status: 200, Time: 0.11s)
2025-10-26 23:22:43,393 - httpx - INFO - [_client.py:1740] - HTTP Request: GET http://127.0.0.1:38697/slow "HTTP/1.1 200 OK"
2025-10-26 23:22:43,396 - configstream.fetcher - INFO - [fetcher.py:270] - Successfully fetched 1 configs from http://127.0.0.1:38697/slow (HTTP/HTTP/1.1, Status: 200, Time: 0.11s)
2025-10-26 23:22:43,413 - httpx - INFO - [_client.py:1740] - HTTP Request: GET http://127.0.0.1:38697/slow "HTTP/1.1 200 OK"
2025-10-26 23:22:43,416 - configstream.fetcher - INFO - [fetcher.py:270] - Successfully fetched 1 configs from http://127.0.0.1:38697/slow (HTTP/HTTP/1.1, Status: 200, Time: 0.11s)
2025-10-26 23:22:43,428 - configstream.fetcher - INFO - [fetcher.py:484] - Fetch complete: 1/10 sources successful (0 not modified), 1 total configs collected
2025-10-26 23:22:43,565 - httpx - INFO - [_client.py:1740] - HTTP Request: GET http://127.0.0.1:43085/source_15 "HTTP/1.1 200 OK"
2025-10-26 23:22:43,569 - configstream.fetcher - INFO - [fetcher.py:270] - Successfully fetched 1 configs from http://127.0.0.1:43085/source_15 (HTTP/HTTP/1.1, Status: 200, Time: 0.06s)
2025-10-26 23:22:43,572 - httpx - INFO - [_client.py:1740] - HTTP Request: GET http://127.0.0.1:43085/source_6 "HTTP/1.1 200 OK"
2025-10-26 23:22:43,578 - configstream.fetcher - INFO - [fetcher.py:270] - Successfully fetched 1 configs from http://127.0.0.1:43085/source_6 (HTTP/HTTP/1.1, Status: 200, Time: 0.05s)
2025-10-26 23:22:43,591 - httpx - INFO - [_client.py:1740] - HTTP Request: GET http://127.0.0.1:43085/source_1 "HTTP/1.1 200 OK"
2025-10-26 23:22:43,594 - configstream.fetcher - INFO - [fetcher.py:270] - Successfully fetched 1 configs from http://127.0.0.1:43085/source_1 (HTTP/HTTP/1.1, Status: 200, Time: 0.05s)
2025-10-26 23:22:43,597 - httpx - INFO - [_client.py:1740] - HTTP Request: GET http://127.0.0.1:43085/source_7 "HTTP/1.1 200 OK"
2025-10-26 23:22:43,600 - configstream.fetcher - INFO - [fetcher.py:270] - Successfully fetched 1 configs from http://127.0.0.1:43085/source_7 (HTTP/HTTP/1.1, Status: 200, Time: 0.02s)
2025-10-26 23:22:43,623 - httpx - INFO - [_client.py:1740] - HTTP Request: GET http://127.0.0.1:43085/source_14 "HTTP/1.1 200 OK"
2025-10-26 23:22:43,626 - configstream.fetcher - INFO - [fetcher.py:270] - Successfully fetched 1 configs from http://127.0.0.1:43085/source_14 (HTTP/HTTP/1.1, Status: 200, Time: 0.04s)
2025-10-26 23:22:43,633 - httpx - INFO - [_client.py:1740] - HTTP Request: GET http://127.0.0.1:43085/source_8 "HTTP/1.1 200 OK"
2025-10-26 23:22:43,636 - configstream.fetcher - INFO - [fetcher.py:270] - Successfully fetched 1 configs from http://127.0.0.1:43085/source_8 (HTTP/HTTP/1.1, Status: 200, Time: 0.03s)
2025-10-26 23:22:43,656 - httpx - INFO - [_client.py:1740] - HTTP Request: GET http://127.0.0.1:43085/source_17 "HTTP/1.1 200 OK"
2025-10-26 23:22:43,659 - configstream.fetcher - INFO - [fetcher.py:270] - Successfully fetched 1 configs from http://127.0.0.1:43085/source_17 (HTTP/HTTP/1.1, Status: 200, Time: 0.03s)
2025-10-26 23:22:43,685 - httpx - INFO - [_client.py:1740] - HTTP Request: GET http://127.0.0.1:43085/source_19 "HTTP/1.1 200 OK"
2025-10-26 23:22:43,688 - configstream.fetcher - INFO - [fetcher.py:270] - Successfully fetched 1 configs from http://127.0.0.1:43085/source_19 (HTTP/HTTP/1.1, Status: 200, Time: 0.04s)
2025-10-26 23:22:43,710 - httpx - INFO - [_client.py:1740] - HTTP Request: GET http://127.0.0.1:43085/source_5 "HTTP/1.1 200 OK"
2025-10-26 23:22:43,714 - configstream.fetcher - INFO - [fetcher.py:270] - Successfully fetched 1 configs from http://127.0.0.1:43085/source_5 (HTTP/HTTP/1.1, Status: 200, Time: 0.02s)
2025-10-26 23:22:43,719 - httpx - INFO - [_client.py:1740] - HTTP Request: GET http://127.0.0.1:43085/source_13 "HTTP/1.1 200 OK"
2025-10-26 23:22:43,722 - configstream.fetcher - INFO - [fetcher.py:270] - Successfully fetched 1 configs from http://127.0.0.1:43085/source_13 (HTTP/HTTP/1.1, Status: 200, Time: 0.06s)
2025-10-26 23:22:43,725 - httpx - INFO - [_client.py:1740] - HTTP Request: GET http://127.0.0.1:43085/source_10 "HTTP/1.1 200 OK"
2025-10-26 23:22:43,728 - configstream.fetcher - INFO - [fetcher.py:270] - Successfully fetched 1 configs from http://127.0.0.1:43085/source_10 (HTTP/HTTP/1.1, Status: 200, Time: 0.02s)
2025-10-26 23:22:43,752 - httpx - INFO - [_client.py:1740] - HTTP Request: GET http://127.0.0.1:43085/source_9 "HTTP/1.1 200 OK"
2025-10-26 23:22:43,755 - configstream.fetcher - INFO - [fetcher.py:270] - Successfully fetched 1 configs from http://127.0.0.1:43085/source_9 (HTTP/HTTP/1.1, Status: 200, Time: 0.02s)
2025-10-26 23:22:43,795 - httpx - INFO - [_client.py:1740] - HTTP Request: GET http://127.0.0.1:43085/source_2 "HTTP/1.1 200 OK"
2025-10-26 23:22:43,798 - configstream.fetcher - INFO - [fetcher.py:270] - Successfully fetched 1 configs from http://127.0.0.1:43085/source_2 (HTTP/HTTP/1.1, Status: 200, Time: 0.05s)
2025-10-26 23:22:43,810 - httpx - INFO - [_client.py:1740] - HTTP Request: GET http://127.0.0.1:43085/source_4 "HTTP/1.1 200 OK"
2025-10-26 23:22:43,814 - configstream.fetcher - INFO - [fetcher.py:270] - Successfully fetched 1 configs from http://127.0.0.1:43085/source_4 (HTTP/HTTP/1.1, Status: 200, Time: 0.03s)
2025-10-26 23:22:43,816 - httpx - INFO - [_client.py:1740] - HTTP Request: GET http://127.0.0.1:43085/source_0 "HTTP/1.1 200 OK"
2025-10-26 23:22:43,819 - configstream.fetcher - INFO - [fetcher.py:270] - Successfully fetched 1 configs from http://127.0.0.1:43085/source_0 (HTTP/HTTP/1.1, Status: 200, Time: 0.05s)
2025-10-26 23:22:43,844 - httpx - INFO - [_client.py:1740] - HTTP Request: GET http://127.0.0.1:43085/source_11 "HTTP/1.1 200 OK"
2025-10-26 23:22:43,848 - configstream.fetcher - INFO - [fetcher.py:270] - Successfully fetched 1 configs from http://127.0.0.1:43085/source_11 (HTTP/HTTP/1.1, Status: 200, Time: 0.04s)
2025-10-26 23:22:43,850 - httpx - INFO - [_client.py:1740] - HTTP Request: GET http://127.0.0.1:43085/source_18 "HTTP/1.1 200 OK"
2025-10-26 23:22:43,855 - configstream.fetcher - INFO - [fetcher.py:270] - Successfully fetched 1 configs from http://127.0.0.1:43085/source_18 (HTTP/HTTP/1.1, Status: 200, Time: 0.03s)
2025-10-26 23:22:43,890 - httpx - INFO - [_client.py:1740] - HTTP Request: GET http://127.0.0.1:43085/source_16 "HTTP/1.1 200 OK"
2025-10-26 23:22:43,893 - configstream.fetcher - INFO - [fetcher.py:270] - Successfully fetched 1 configs from http://127.0.0.1:43085/source_16 (HTTP/HTTP/1.1, Status: 200, Time: 0.03s)
2025-10-26 23:22:43,898 - httpx - INFO - [_client.py:1740] - HTTP Request: GET http://127.0.0.1:43085/source_3 "HTTP/1.1 200 OK"
2025-10-26 23:22:43,901 - configstream.fetcher - INFO - [fetcher.py:270] - Successfully fetched 1 configs from http://127.0.0.1:43085/source_3 (HTTP/HTTP/1.1, Status: 200, Time: 0.05s)
2025-10-26 23:22:43,939 - httpx - INFO - [_client.py:1740] - HTTP Request: GET http://127.0.0.1:43085/source_12 "HTTP/1.1 200 OK"
2025-10-26 23:22:43,943 - configstream.fetcher - INFO - [fetcher.py:270] - Successfully fetched 1 configs from http://127.0.0.1:43085/source_12 (HTTP/HTTP/1.1, Status: 200, Time: 0.06s)
2025-10-26 23:22:43,953 - configstream.fetcher - INFO - [fetcher.py:484] - Fetch complete: 20/20 sources successful (0 not modified), 20 total configs collected
2025-10-26 23:22:44,039 - httpx - INFO - [_client.py:1740] - HTTP Request: GET http://127.0.0.1:42043/s2 "HTTP/1.1 200 OK"
2025-10-26 23:22:44,043 - configstream.fetcher - INFO - [fetcher.py:270] - Successfully fetched 1 configs from http://127.0.0.1:42043/s2 (HTTP/HTTP/1.1, Status: 200, Time: 0.01s)
2025-10-26 23:22:44,055 - httpx - INFO - [_client.py:1740] - HTTP Request: GET http://127.0.0.1:42043/s1 "HTTP/1.1 200 OK"
2025-10-26 23:22:44,058 - configstream.fetcher - INFO - [fetcher.py:270] - Successfully fetched 2 configs from http://127.0.0.1:42043/s1 (HTTP/HTTP/1.1, Status: 200, Time: 0.01s)
2025-10-26 23:22:44,068 - configstream.fetcher - INFO - [fetcher.py:484] - Fetch complete: 2/2 sources successful (0 not modified), 3 total configs collected
2025-10-26 23:22:44,149 - httpx - INFO - [_client.py:1740] - HTTP Request: GET http://127.0.0.1:45863/many "HTTP/1.1 200 OK"
2025-10-26 23:22:44,153 - configstream.fetcher - INFO - [fetcher.py:270] - Successfully fetched 100 configs from http://127.0.0.1:45863/many (HTTP/HTTP/1.1, Status: 200, Time: 0.01s)
2025-10-26 23:22:44,161 - configstream.fetcher - INFO - [fetcher.py:484] - Fetch complete: 1/1 sources successful (0 not modified), 100 total configs collected
2025-10-26 23:22:44,189 - configstream.pipeline - WARNING - [pipeline.py:103] - Skipping invalid source 'ftp://invalid.com': Unsupported URL scheme: ftp
2025-10-26 23:22:44,192 - configstream.pipeline - WARNING - [pipeline.py:103] - Skipping invalid source '': Source is empty
2025-10-26 23:22:44,217 - configstream.pipeline - INFO - [pipeline.py:217] - No usable configurations found in http://example.com/source
2025-10-26 23:22:44,228 - configstream.geoip - INFO - [geoip.py:39] - GeoIP not configured (MAXMIND_LICENSE_KEY not set); skipping.
2025-10-26 23:22:44,230 - configstream.pipeline - INFO - [pipeline.py:279] - Starting pipeline with 1 sources and 0 supplied proxies
2025-10-26 23:22:44,232 - configstream.pipeline - INFO - [pipeline.py:353] - PIPELINE: Fetched 1 raw proxy configs.
2025-10-26 23:22:44,234 - configstream.pipeline - INFO - [pipeline.py:372] - PIPELINE: Prepared 1 unique configs for sequential processing.
2025-10-26 23:22:44,236 - configstream.pipeline - INFO - [pipeline.py:394] - Using effective test timeout of 10.00s
2025-10-26 23:22:44,243 - configstream.test_cache - INFO - [test_cache.py:71] - Test cache initialized at data/test_cache.db with WAL mode
2025-10-26 23:22:44,246 - configstream.pipeline - INFO - [pipeline.py:398] - Test cache initialized: {'total_entries': 0, 'valid_entries': 0, 'expired_entries': 0, 'average_health_score': 0.0, 'ttl_seconds': 86400}
2025-10-26 23:22:44,260 - configstream.security_validator - INFO - [security_validator.py:378] - Security validation: 1/1 proxies passed
2025-10-26 23:22:44,264 - configstream.pipeline - WARNING - [pipeline.py:452] - GeoIP database not found at data/GeoLite2-City.mmdb
2025-10-26 23:22:44,267 - configstream.pipeline - INFO - [pipeline.py:825] - Filtered phase-1 to 1 proxies with latency <= 5000ms
2025-10-26 23:22:44,281 - configstream.pipeline - INFO - [pipeline.py:643] - Generated 3 categorized output files
2025-10-26 23:22:44,283 - configstream.pipeline - INFO - [pipeline.py:905] - Pipeline completed successfully in 0.1 seconds
2025-10-26 23:22:44,292 - configstream.pipeline - ERROR - [pipeline.py:265] - No sources provided and no proxies supplied for retest
2025-10-26 23:22:44,301 - configstream.geoip - INFO - [geoip.py:39] - GeoIP not configured (MAXMIND_LICENSE_KEY not set); skipping.
2025-10-26 23:22:44,303 - configstream.pipeline - INFO - [pipeline.py:279] - Starting pipeline with 1 sources and 0 supplied proxies
2025-10-26 23:22:44,305 - configstream.pipeline - INFO - [pipeline.py:353] - PIPELINE: Fetched 1 raw proxy configs.
2025-10-26 23:22:44,307 - configstream.pipeline - INFO - [pipeline.py:372] - PIPELINE: Prepared 1 unique configs for sequential processing.
2025-10-26 23:22:44,308 - configstream.pipeline - INFO - [pipeline.py:394] - Using effective test timeout of 10.00s
2025-10-26 23:22:44,310 - configstream.test_cache - INFO - [test_cache.py:71] - Test cache initialized at data/test_cache.db with WAL mode
2025-10-26 23:22:44,312 - configstream.pipeline - INFO - [pipeline.py:398] - Test cache initialized: {'total_entries': 0, 'valid_entries': 0, 'expired_entries': 0, 'average_health_score': 0.0, 'ttl_seconds': 86400}
2025-10-26 23:22:44,315 - configstream.security_validator - INFO - [security_validator.py:378] - Security validation: 1/1 proxies passed
2025-10-26 23:22:44,317 - configstream.pipeline - WARNING - [pipeline.py:452] - GeoIP database not found at data/GeoLite2-City.mmdb
2025-10-26 23:22:44,319 - configstream.pipeline - INFO - [pipeline.py:825] - Filtered phase-1 to 0 proxies with latency <= 5000ms
2025-10-26 23:22:44,321 - configstream.pipeline - WARNING - [pipeline.py:852] - No working proxies detected in phase-1; keeping tested proxies as fallback
2025-10-26 23:22:44,330 - configstream.pipeline - INFO - [pipeline.py:643] - Generated 2 categorized output files
2025-10-26 23:22:44,332 - configstream.pipeline - WARNING - [pipeline.py:899] - No proxies passed all filters across all phases
2025-10-26 23:22:44,334 - configstream.pipeline - INFO - [pipeline.py:905] - Pipeline completed successfully in 0.0 seconds
2025-10-26 23:22:44,345 - configstream.geoip - INFO - [geoip.py:39] - GeoIP not configured (MAXMIND_LICENSE_KEY not set); skipping.
2025-10-26 23:22:44,347 - configstream.pipeline - INFO - [pipeline.py:279] - Starting pipeline with 1 sources and 0 supplied proxies
2025-10-26 23:22:44,349 - configstream.pipeline - INFO - [pipeline.py:353] - PIPELINE: Fetched 3 raw proxy configs.
2025-10-26 23:22:44,351 - configstream.pipeline - INFO - [pipeline.py:372] - PIPELINE: Prepared 3 unique configs for sequential processing.
2025-10-26 23:22:44,352 - configstream.pipeline - INFO - [pipeline.py:394] - Using effective test timeout of 10.00s
2025-10-26 23:22:44,354 - configstream.test_cache - INFO - [test_cache.py:71] - Test cache initialized at data/test_cache.db with WAL mode
2025-10-26 23:22:44,356 - configstream.pipeline - INFO - [pipeline.py:398] - Test cache initialized: {'total_entries': 0, 'valid_entries': 0, 'expired_entries': 0, 'average_health_score': 0.0, 'ttl_seconds': 86400}
2025-10-26 23:22:44,359 - configstream.security_validator - INFO - [security_validator.py:378] - Security validation: 3/3 proxies passed
2025-10-26 23:22:44,361 - configstream.pipeline - INFO - [pipeline.py:771] - Limiting phase-1 to 2 proxies to respect max_proxies
2025-10-26 23:22:44,363 - configstream.pipeline - WARNING - [pipeline.py:452] - GeoIP database not found at data/GeoLite2-City.mmdb
2025-10-26 23:22:44,366 - configstream.pipeline - INFO - [pipeline.py:825] - Filtered phase-1 to 2 proxies with latency <= 5000ms
2025-10-26 23:22:44,382 - configstream.pipeline - INFO - [pipeline.py:643] - Generated 3 categorized output files
2025-10-26 23:22:44,384 - configstream.pipeline - INFO - [pipeline.py:905] - Pipeline completed successfully in 0.0 seconds
2025-10-26 23:22:44,395 - configstream.geoip - INFO - [geoip.py:39] - GeoIP not configured (MAXMIND_LICENSE_KEY not set); skipping.
2025-10-26 23:22:44,397 - configstream.pipeline - INFO - [pipeline.py:279] - Starting pipeline with 0 sources and 3 supplied proxies
2025-10-26 23:22:44,398 - configstream.pipeline - INFO - [pipeline.py:353] - PIPELINE: Fetched 0 raw proxy configs.
2025-10-26 23:22:44,400 - configstream.pipeline - INFO - [pipeline.py:372] - PIPELINE: Prepared 0 unique configs for sequential processing.
2025-10-26 23:22:44,401 - configstream.pipeline - INFO - [pipeline.py:381] - Using 3 supplied proxies
2025-10-26 23:22:44,403 - configstream.pipeline - INFO - [pipeline.py:394] - Using effective test timeout of 1.00s
2025-10-26 23:22:44,405 - configstream.test_cache - INFO - [test_cache.py:71] - Test cache initialized at data/test_cache.db with WAL mode
2025-10-26 23:22:44,407 - configstream.pipeline - INFO - [pipeline.py:398] - Test cache initialized: {'total_entries': 0, 'valid_entries': 0, 'expired_entries': 0, 'average_health_score': 0.0, 'ttl_seconds': 86400}
2025-10-26 23:22:44,410 - configstream.pipeline - WARNING - [pipeline.py:452] - GeoIP database not found at data/GeoLite2-City.mmdb
2025-10-26 23:22:44,412 - configstream.pipeline - INFO - [pipeline.py:798] - Filtered phase-1 to 2 proxies in US
2025-10-26 23:22:44,414 - configstream.pipeline - INFO - [pipeline.py:811] - Filtered phase-1 to 2 proxies with latency >= 50ms
2025-10-26 23:22:44,416 - configstream.pipeline - INFO - [pipeline.py:825] - Filtered phase-1 to 1 proxies with latency <= 1000ms
2025-10-26 23:22:44,431 - configstream.pipeline - INFO - [pipeline.py:643] - Generated 5 categorized output files
2025-10-26 23:22:44,433 - configstream.pipeline - INFO - [pipeline.py:905] - Pipeline completed successfully in 0.0 seconds
2025-10-26 23:22:44,443 - configstream.geoip - INFO - [geoip.py:39] - GeoIP not configured (MAXMIND_LICENSE_KEY not set); skipping.
2025-10-26 23:22:44,445 - configstream.pipeline - INFO - [pipeline.py:279] - Starting pipeline with 1 sources and 0 supplied proxies
2025-10-26 23:22:44,487 - configstream.pipeline - INFO - [pipeline.py:353] - PIPELINE: Fetched 1 raw proxy configs.
2025-10-26 23:22:44,489 - configstream.pipeline - INFO - [pipeline.py:372] - PIPELINE: Prepared 1 unique configs for sequential processing.
2025-10-26 23:22:44,490 - configstream.pipeline - INFO - [pipeline.py:394] - Using effective test timeout of 10.00s
2025-10-26 23:22:44,493 - configstream.test_cache - INFO - [test_cache.py:71] - Test cache initialized at data/test_cache.db with WAL mode
2025-10-26 23:22:44,495 - configstream.pipeline - INFO - [pipeline.py:398] - Test cache initialized: {'total_entries': 0, 'valid_entries': 0, 'expired_entries': 0, 'average_health_score': 0.0, 'ttl_seconds': 86400}
2025-10-26 23:22:44,497 - configstream.security_validator - INFO - [security_validator.py:378] - Security validation: 1/1 proxies passed
2025-10-26 23:22:44,500 - configstream.pipeline - WARNING - [pipeline.py:452] - GeoIP database not found at data/GeoLite2-City.mmdb
2025-10-26 23:22:44,502 - configstream.pipeline - INFO - [pipeline.py:825] - Filtered phase-1 to 1 proxies with latency <= 5000ms
2025-10-26 23:22:44,513 - configstream.pipeline - INFO - [pipeline.py:643] - Generated 3 categorized output files
2025-10-26 23:22:44,515 - configstream.pipeline - INFO - [pipeline.py:905] - Pipeline completed successfully in 0.1 seconds
2025-10-26 23:22:44,565 - configstream.pipeline - WARNING - [pipeline.py:340] - Failed to fetch http://failing-remote.com/source: Fetch failed!
2025-10-26 23:22:44,569 - configstream.pipeline - ERROR - [pipeline.py:884] - No configurations could be parsed
2025-10-26 23:22:44,578 - configstream.geoip - INFO - [geoip.py:39] - GeoIP not configured (MAXMIND_LICENSE_KEY not set); skipping.
2025-10-26 23:22:44,580 - configstream.pipeline - INFO - [pipeline.py:279] - Starting pipeline with 1 sources and 0 supplied proxies
2025-10-26 23:22:44,582 - configstream.pipeline - INFO - [pipeline.py:353] - PIPELINE: Fetched 0 raw proxy configs.
2025-10-26 23:22:44,583 - configstream.pipeline - INFO - [pipeline.py:372] - PIPELINE: Prepared 0 unique configs for sequential processing.
2025-10-26 23:22:44,585 - configstream.pipeline - INFO - [pipeline.py:394] - Using effective test timeout of 10.00s
2025-10-26 23:22:44,587 - configstream.test_cache - INFO - [test_cache.py:71] - Test cache initialized at data/test_cache.db with WAL mode
2025-10-26 23:22:44,589 - configstream.pipeline - INFO - [pipeline.py:398] - Test cache initialized: {'total_entries': 0, 'valid_entries': 0, 'expired_entries': 0, 'average_health_score': 0.0, 'ttl_seconds': 86400}
2025-10-26 23:22:44,591 - configstream.pipeline - ERROR - [pipeline.py:884] - No configurations could be parsed
2025-10-26 23:22:44,601 - configstream.pipeline - ERROR - [pipeline.py:265] - No sources provided and no proxies supplied for retest
2025-10-26 23:22:44,610 - configstream.geoip - INFO - [geoip.py:39] - GeoIP not configured (MAXMIND_LICENSE_KEY not set); skipping.
2025-10-26 23:22:44,612 - configstream.pipeline - INFO - [pipeline.py:279] - Starting pipeline with 1 sources and 0 supplied proxies
2025-10-26 23:22:44,614 - configstream.pipeline - INFO - [pipeline.py:353] - PIPELINE: Fetched 1 raw proxy configs.
2025-10-26 23:22:44,616 - configstream.pipeline - INFO - [pipeline.py:372] - PIPELINE: Prepared 1 unique configs for sequential processing.
2025-10-26 23:22:44,617 - configstream.pipeline - INFO - [pipeline.py:394] - Using effective test timeout of 10.00s
2025-10-26 23:22:44,619 - configstream.test_cache - INFO - [test_cache.py:71] - Test cache initialized at data/test_cache.db with WAL mode
2025-10-26 23:22:44,621 - configstream.pipeline - INFO - [pipeline.py:398] - Test cache initialized: {'total_entries': 0, 'valid_entries': 0, 'expired_entries': 0, 'average_health_score': 0.0, 'ttl_seconds': 86400}
2025-10-26 23:22:44,623 - configstream.security_validator - INFO - [security_validator.py:378] - Security validation: 1/1 proxies passed
2025-10-26 23:22:44,626 - configstream.pipeline - WARNING - [pipeline.py:452] - GeoIP database not found at data/GeoLite2-City.mmdb
2025-10-26 23:22:44,628 - configstream.pipeline - INFO - [pipeline.py:825] - Filtered phase-1 to 1 proxies with latency <= 5000ms
2025-10-26 23:22:44,639 - configstream.pipeline - INFO - [pipeline.py:643] - Generated 3 categorized output files
2025-10-26 23:22:44,641 - configstream.pipeline - INFO - [pipeline.py:905] - Pipeline completed successfully in 0.0 seconds
2025-10-26 23:22:44,651 - configstream.geoip - INFO - [geoip.py:39] - GeoIP not configured (MAXMIND_LICENSE_KEY not set); skipping.
2025-10-26 23:22:44,653 - configstream.pipeline - INFO - [pipeline.py:279] - Starting pipeline with 1 sources and 0 supplied proxies
2025-10-26 23:22:44,655 - configstream.pipeline - INFO - [pipeline.py:353] - PIPELINE: Fetched 1 raw proxy configs.
2025-10-26 23:22:44,656 - configstream.pipeline - INFO - [pipeline.py:372] - PIPELINE: Prepared 1 unique configs for sequential processing.
2025-10-26 23:22:44,658 - configstream.pipeline - INFO - [pipeline.py:394] - Using effective test timeout of 10.00s
2025-10-26 23:22:44,660 - configstream.test_cache - INFO - [test_cache.py:71] - Test cache initialized at data/test_cache.db with WAL mode
2025-10-26 23:22:44,662 - configstream.pipeline - INFO - [pipeline.py:398] - Test cache initialized: {'total_entries': 0, 'valid_entries': 0, 'expired_entries': 0, 'average_health_score': 0.0, 'ttl_seconds': 86400}
2025-10-26 23:22:44,664 - configstream.security_validator - WARNING - [security_validator.py:110] - Suspicious address pattern: 127.0.0.1
2025-10-26 23:22:44,666 - configstream.security_validator - WARNING - [security_validator.py:370] - Insecure proxy filtered: 127.0.0.1:443
2025-10-26 23:22:44,667 - configstream.security_validator - INFO - [security_validator.py:378] - Security validation: 0/1 proxies passed
2025-10-26 23:22:44,669 - configstream.pipeline - INFO - [pipeline.py:712] - 1 insecure proxies were filtered out
2025-10-26 23:22:44,671 - configstream.pipeline - ERROR - [pipeline.py:884] - No configurations could be parsed or all were deemed insecure
2025-10-26 23:22:44,694 - configstream.geoip - INFO - [geoip.py:39] - GeoIP not configured (MAXMIND_LICENSE_KEY not set); skipping.
2025-10-26 23:22:44,696 - configstream.pipeline - INFO - [pipeline.py:279] - Starting pipeline with 1 sources and 0 supplied proxies
2025-10-26 23:22:44,744 - configstream.pipeline - INFO - [pipeline.py:353] - PIPELINE: Fetched 1010 raw proxy configs.
2025-10-26 23:22:44,748 - configstream.pipeline - INFO - [pipeline.py:372] - PIPELINE: Prepared 1010 unique configs for sequential processing.
2025-10-26 23:22:44,749 - configstream.pipeline - INFO - [pipeline.py:394] - Using effective test timeout of 10.00s
2025-10-26 23:22:44,751 - configstream.test_cache - INFO - [test_cache.py:71] - Test cache initialized at data/test_cache.db with WAL mode
2025-10-26 23:22:44,754 - configstream.pipeline - INFO - [pipeline.py:398] - Test cache initialized: {'total_entries': 0, 'valid_entries': 0, 'expired_entries': 0, 'average_health_score': 0.0, 'ttl_seconds': 86400}
2025-10-26 23:22:45,009 - configstream.security_validator - INFO - [security_validator.py:378] - Security validation: 1010/1010 proxies passed
2025-10-26 23:22:45,073 - configstream.pipeline - INFO - [pipeline.py:423] - Testing batch 1/2 (1000 proxies) for phase-1
2025-10-26 23:22:45,214 - configstream.pipeline - INFO - [pipeline.py:423] - Testing batch 2/2 (10 proxies) for phase-1
2025-10-26 23:22:45,219 - configstream.pipeline - WARNING - [pipeline.py:452] - GeoIP database not found at data/GeoLite2-City.mmdb
2025-10-26 23:22:45,318 - configstream.pipeline - INFO - [pipeline.py:825] - Filtered phase-1 to 1010 proxies with latency <= 5000ms
2025-10-26 23:22:47,185 - configstream.pipeline - INFO - [pipeline.py:643] - Generated 4 categorized output files
2025-10-26 23:22:47,188 - configstream.pipeline - INFO - [pipeline.py:905] - Pipeline completed successfully in 2.5 seconds
2025-10-26 23:22:47,521 - configstream.async_file_ops - ERROR - [async_file_ops.py:103] - File not found: /tmp/pytest-of-jules/pytest-16/test_read_file_async_not_found0/does_not_exist.txt
2025-10-26 23:22:47,554 - configstream.async_file_ops - INFO - [async_file_ops.py:239] - Read 10/10 files successfully
2025-10-26 23:22:47,563 - configstream.async_file_ops - WARNING - [async_file_ops.py:227] - Failed to read /tmp/pytest-of-jules/pytest-16/test_read_multiple_files_handl0/missing.txt: [Errno 2] No such file or directory: '/tmp/pytest-of-jules/pytest-16/test_read_multiple_files_handl0/missing.txt'
2025-10-26 23:22:47,567 - configstream.async_file_ops - INFO - [async_file_ops.py:239] - Read 2/3 files successfully
2025-10-26 23:22:47,854 - configstream.async_file_ops - INFO - [async_file_ops.py:239] - Read 100/100 files successfully
2025-10-26 23:22:47,866 - configstream.test_cache - INFO - [test_cache.py:71] - Test cache initialized at /tmp/pytest-of-jules/pytest-16/test_warm_cache_prioritizes_hi0/test_cache.db with WAL mode
2025-10-26 23:22:48,012 - configstream.test_cache - INFO - [test_cache.py:71] - Test cache initialized at /tmp/pytest-of-jules/pytest-16/test_warm_cache_with_no_cached0/test_cache.db with WAL mode
2025-10-26 23:22:48,027 - configstream.test_cache - INFO - [test_cache.py:71] - Test cache initialized at /tmp/pytest-of-jules/pytest-16/test_warm_cache_with_all_cache0/test_cache.db with WAL mode
2025-10-26 23:22:48,238 - configstream.test_cache - INFO - [test_cache.py:71] - Test cache initialized at /tmp/pytest-of-jules/pytest-16/test_warm_cache_with_empty_lis0/test_cache.db with WAL mode
2025-10-26 23:22:48,257 - configstream.test_cache - INFO - [test_cache.py:71] - Test cache initialized at /tmp/pytest-of-jules/pytest-16/test_warm_cache_ordering_corre0/test_cache.db with WAL mode
2025-10-26 23:22:48,495 - configstream.fetcher - WARNING - [fetcher.py:318] - HTTP error fetching http://example.com: Server error: 500
2025-10-26 23:22:48,643 - configstream.fetcher - WARNING - [fetcher.py:318] - HTTP error fetching http://example.com: Server error: 502
2025-10-26 23:22:48,768 - configstream.fetcher - WARNING - [fetcher.py:322] - HTTP error fetching http://example.com: test error
2025-10-26 23:22:48,770 - configstream.fetcher - ERROR - [fetcher.py:345] - Failed to fetch http://example.com after 3 attempts. Last error: HTTP error: test error
2025-10-26 23:22:48,778 - configstream.fetcher - WARNING - [fetcher.py:234] - Unexpected content type for http://example.com: text/html
2025-10-26 23:22:48,781 - configstream.fetcher - INFO - [fetcher.py:270] - Successfully fetched 2 configs from http://example.com (HTTP/<AsyncMock name='mock.get().http_version' id='140203982447360'>, Status: 200, Time: 0.00s)
2025-10-26 23:22:48,789 - configstream.fetcher - WARNING - [fetcher.py:287] - Rate limit hit for http://example.com (host: example.com); retrying in 0.1s (attempt 1/2)
2025-10-26 23:22:49,026 - configstream.fetcher - INFO - [fetcher.py:270] - Successfully fetched 1 configs from http://example.com (HTTP/<AsyncMock name='mock.http_version' id='140203933290560'>, Status: 200, Time: 0.00s)
2025-10-26 23:22:49,034 - configstream.fetcher - WARNING - [fetcher.py:309] - Timeout fetching http://example.com (attempt 1/1)
2025-10-26 23:22:49,036 - configstream.fetcher - ERROR - [fetcher.py:345] - Failed to fetch http://example.com after 1 attempts. Last error: Timeout after 30 seconds
2025-10-26 23:22:49,043 - configstream.fetcher - ERROR - [fetcher.py:115] - URL validation failed for invalid-url: Invalid URL format: invalid-url
2025-10-26 23:22:49,094 - configstream.fetcher - ERROR - [fetcher.py:470] - Unhandled exception for http://example.com/source1: Unhandled test exception
2025-10-26 23:22:49,102 - configstream.fetcher - INFO - [fetcher.py:484] - Fetch complete: 1/2 sources successful (0 not modified), 1 total configs collected
2025-10-26 23:22:49,139 - configstream.test_cache - INFO - [test_cache.py:71] - Test cache initialized at /tmp/tmpj68jgnop/test.db with WAL mode
2025-10-26 23:22:49,252 - httpx - INFO - [_client.py:1740] - HTTP Request: GET http://ip-api.com/json/192.168.1.1?fields=status,country,countryCode,city,as "HTTP/1.1 200 OK"
2025-10-26 23:22:49,266 - configstream.test_cache - INFO - [test_cache.py:71] - Test cache initialized at /tmp/tmptvghh8ak/test.db with WAL mode
2025-10-26 23:22:49,287 - configstream.test_cache - INFO - [test_cache.py:71] - Test cache initialized at /tmp/tmp8_6j2p9v/cache.db with WAL mode
2025-10-26 23:22:49,298 - configstream.security_validator - WARNING - [security_validator.py:334] - Security validation is running in leniency mode. No proxies will be filtered.
2025-10-26 23:22:49,301 - configstream.security_validator - INFO - [security_validator.py:354] - Security validation (leniency mode): Detected 0 insecure proxies, but not filtering.
2025-10-26 23:22:49,302 - configstream.security_validator - WARNING - [security_validator.py:334] - Security validation is running in leniency mode. No proxies will be filtered.
2025-10-26 23:22:49,304 - configstream.security_validator - INFO - [security_validator.py:354] - Security validation (leniency mode): Detected 0 insecure proxies, but not filtering.
2025-10-26 23:22:49,405 - httpx - INFO - [_client.py:1740] - HTTP Request: GET http://ip-api.com/json/127.0.0.1?fields=status,country,countryCode,city,as "HTTP/1.1 200 OK"
2025-10-26 23:22:49,505 - httpx - INFO - [_client.py:1740] - HTTP Request: GET http://ip-api.com/json/::1?fields=status,country,countryCode,city,as "HTTP/1.1 200 OK"
2025-10-26 23:22:49,605 - httpx - INFO - [_client.py:1740] - HTTP Request: GET http://ip-api.com/json/unknown.test?fields=status,country,countryCode,city,as "HTTP/1.1 200 OK"
2025-10-26 23:22:49,622 - configstream.test_cache - INFO - [test_cache.py:71] - Test cache initialized at /tmp/tmpgpkpc3sy/test.db with WAL mode
2025-10-26 23:22:50,730 - configstream.test_cache - INFO - [test_cache.py:243] - Cleaned up 1 expired cache entries
2025-10-26 23:22:50,743 - configstream.geoip - INFO - [geoip.py:39] - GeoIP not configured (MAXMIND_LICENSE_KEY not set); skipping.
2025-10-26 23:22:50,754 - configstream.geoip - INFO - [geoip.py:49] - Downloading GeoLite2-Country...
2025-10-26 23:22:50,757 - configstream.geoip - INFO - [geoip.py:51] - GeoLite2-Country downloaded successfully
2025-10-26 23:22:50,758 - configstream.geoip - INFO - [geoip.py:49] - Downloading GeoLite2-City...
2025-10-26 23:22:50,760 - configstream.geoip - INFO - [geoip.py:51] - GeoLite2-City downloaded successfully
2025-10-26 23:22:50,770 - configstream.geoip - INFO - [geoip.py:49] - Downloading GeoLite2-Country...
2025-10-26 23:22:50,772 - configstream.geoip - ERROR - [geoip.py:54] - Failed to download GeoLite2-Country: Download failed
2025-10-26 23:22:50,774 - configstream.geoip - INFO - [geoip.py:49] - Downloading GeoLite2-City...
2025-10-26 23:22:50,776 - configstream.geoip - ERROR - [geoip.py:54] - Failed to download GeoLite2-City: Download failed
2025-10-26 23:22:50,954 - configstream.intelligent_fallback - INFO - [intelligent_fallback.py:62] - Saved 10 proxies for fallback use
2025-10-26 23:22:51,047 - configstream.intelligent_fallback - INFO - [intelligent_fallback.py:62] - Saved 600 proxies for fallback use
2025-10-26 23:22:51,055 - configstream.intelligent_fallback - WARNING - [intelligent_fallback.py:40] - No proxies to save for fallback
2025-10-26 23:22:51,063 - configstream.intelligent_fallback - INFO - [intelligent_fallback.py:62] - Saved 10 proxies for fallback use
2025-10-26 23:22:51,065 - configstream.intelligent_fallback - INFO - [intelligent_fallback.py:92] - Loaded 10 fallback proxies from 2025-10-26T23:22:51.061424+00:00
2025-10-26 23:22:51,071 - configstream.intelligent_fallback - WARNING - [intelligent_fallback.py:72] - No fallback data available
2025-10-26 23:22:51,077 - configstream.intelligent_fallback - ERROR - [intelligent_fallback.py:100] - Failed to load fallback data: Expecting property name enclosed in double quotes: line 1 column 3 (char 2)
2025-10-26 23:22:51,085 - configstream.intelligent_fallback - INFO - [intelligent_fallback.py:92] - Loaded 1 fallback proxies from 2025-10-23T00:00:00Z
2025-10-26 23:22:51,098 - configstream.intelligent_fallback - INFO - [intelligent_fallback.py:62] - Saved 1 proxies for fallback use
2025-10-26 23:22:51,099 - configstream.intelligent_fallback - INFO - [intelligent_fallback.py:92] - Loaded 1 fallback proxies from 2025-10-26T23:22:51.097649+00:00
2025-10-26 23:22:51,174 - configstream.parsers - WARNING - [parsers.py:40] - Invalid base64 characters: {'-'}
2025-10-26 23:22:51,179 - configstream.parsers - WARNING - [parsers.py:40] - Invalid base64 characters: {'-'}
2025-10-26 23:22:51,180 - configstream.parsers - WARNING - [parsers.py:40] - Invalid base64 characters: {'-'}
2025-10-26 23:22:51,218 - configstream.parsers - WARNING - [parsers.py:26] - Expected string, got NoneType
2025-10-26 23:22:51,577 - configstream.parsers - ERROR - [parsers.py:35] - Base64 input too large: 52428801 bytes (max: 52428800)
2025-10-26 23:22:51,583 - configstream.parsers - WARNING - [parsers.py:40] - Invalid base64 characters: {'!', '*', '#', '%', '@', ')', '&', '(', '^', '$'}
2025-10-26 23:22:51,591 - configstream.parsers - WARNING - [parsers.py:40] - Invalid base64 characters: {'!'}
2025-10-26 23:22:51,607 - configstream.parsers - WARNING - [parsers.py:102] - Payload has 15000 lines, truncating to 10000
2025-10-26 23:22:51,712 - configstream.parsers - WARNING - [parsers.py:123] - VMess config too long: 20000 bytes
2025-10-26 23:22:51,718 - configstream.parsers - WARNING - [parsers.py:72] - Base64 decode failed: Invalid base64-encoded string: number of data characters (13) cannot be 1 more than a multiple of 4
2025-10-26 23:22:51,786 - configstream.parsers - WARNING - [parsers.py:69] - Decoded data is not valid UTF-8
2025-10-26 23:22:51,805 - configstream.parsers - WARNING - [parsers.py:40] - Invalid base64 characters: {'!', '*', '#', '%', '@', ')', '&', '(', '^', '$'}
2025-10-26 23:22:51,937 - configstream.parsers - ERROR - [parsers.py:35] - Base64 input too large: 62914560 bytes (max: 52428800)
2025-10-26 23:22:51,944 - configstream.parsers - WARNING - [parsers.py:26] - Expected string, got int
2025-10-26 23:22:51,986 - configstream.parsers - WARNING - [parsers.py:40] - Invalid base64 characters: {'@', '!', '#'}
2025-10-26 23:22:51,988 - configstream.parsers - WARNING - [parsers.py:40] - Invalid base64 characters: {'@', '!', '#'}
2025-10-26 23:22:52,067 - configstream.pipeline - WARNING - [pipeline.py:103] - Skipping invalid source '': Source is empty
2025-10-26 23:22:52,069 - configstream.pipeline - WARNING - [pipeline.py:103] - Skipping invalid source 'ftp://invalid.com': Unsupported URL scheme: ftp
2025-10-26 23:22:52,203 - configstream.proxy_history - INFO - [proxy_history.py:211] - Exported history visualization data to /tmp/pytest-of-jules/pytest-16/test_export_for_visualization0/viz.json
2025-10-26 23:22:52,209 - configstream.proxy_history - INFO - [proxy_history.py:211] - Exported history visualization data to /tmp/pytest-of-jules/pytest-16/test_export_skips_empty_entrie0/viz.json
2025-10-26 23:22:52,217 - configstream.proxy_history - INFO - [proxy_history.py:247] - Cleaned up history for 1 proxies
2025-10-26 23:22:53,435 - configstream.security_validator - WARNING - [security_validator.py:92] - Dangerous port detected: 21
2025-10-26 23:22:53,437 - configstream.security_validator - WARNING - [security_validator.py:92] - Dangerous port detected: 22
2025-10-26 23:22:53,438 - configstream.security_validator - WARNING - [security_validator.py:92] - Dangerous port detected: 23
2025-10-26 23:22:53,444 - configstream.security_validator - WARNING - [security_validator.py:110] - Suspicious address pattern: localhost
2025-10-26 23:22:53,446 - configstream.security_validator - WARNING - [security_validator.py:110] - Suspicious address pattern: 127.0.0.1
2025-10-26 23:22:53,447 - configstream.security_validator - WARNING - [security_validator.py:110] - Suspicious address pattern: 0.0.0.0
2025-10-26 23:22:53,451 - configstream.security_validator - WARNING - [security_validator.py:110] - Suspicious address pattern: 192.168.1.1
2025-10-26 23:22:53,452 - configstream.security_validator - WARNING - [security_validator.py:110] - Suspicious address pattern: 10.0.0.1
2025-10-26 23:22:53,454 - configstream.security_validator - WARNING - [security_validator.py:138] - Private IP range detected: 172.16.0.1
2025-10-26 23:22:53,455 - configstream.security_validator - WARNING - [security_validator.py:138] - Private IP range detected: 172.31.255.255
2025-10-26 23:22:53,456 - configstream.security_validator - WARNING - [security_validator.py:110] - Suspicious address pattern: 169.254.1.1
2025-10-26 23:22:53,462 - configstream.security_validator - WARNING - [security_validator.py:156] - Special address detected: ::1
2025-10-26 23:22:53,464 - configstream.security_validator - WARNING - [security_validator.py:156] - Special address detected: fe80::1
2025-10-26 23:22:53,465 - configstream.security_validator - WARNING - [security_validator.py:156] - Special address detected: fc00::1
2025-10-26 23:22:53,467 - configstream.security_validator - WARNING - [security_validator.py:156] - Special address detected: fd00::1
2025-10-26 23:22:53,470 - configstream.security_validator - WARNING - [security_validator.py:164] - Non-standard IP notation: 0x7f000001
2025-10-26 23:22:53,472 - configstream.security_validator - WARNING - [security_validator.py:164] - Non-standard IP notation: 0177.0.0.1
2025-10-26 23:22:53,483 - configstream.security_validator - ERROR - [security_validator.py:188] - Null byte detected in config
2025-10-26 23:22:53,486 - configstream.security_validator - ERROR - [security_validator.py:213] - Suspicious pattern detected: \$\(
2025-10-26 23:22:53,488 - configstream.security_validator - ERROR - [security_validator.py:213] - Suspicious pattern detected: ;\s*rm\s
2025-10-26 23:22:53,489 - configstream.security_validator - ERROR - [security_validator.py:213] - Suspicious pattern detected: &&\s*rm\s
2025-10-26 23:22:53,490 - configstream.security_validator - ERROR - [security_validator.py:213] - Suspicious pattern detected: \|\s*sh
2025-10-26 23:22:53,492 - configstream.security_validator - ERROR - [security_validator.py:213] - Suspicious pattern detected: `
2025-10-26 23:22:53,493 - configstream.security_validator - ERROR - [security_validator.py:213] - Suspicious pattern detected: eval\s*\(
2025-10-26 23:22:53,498 - configstream.security_validator - WARNING - [security_validator.py:221] - Config too long: 15008 chars
2025-10-26 23:22:53,512 - configstream.security_validator - WARNING - [security_validator.py:110] - Suspicious address pattern: localhost
2025-10-26 23:22:53,513 - configstream.security_validator - WARNING - [security_validator.py:110] - Suspicious address pattern: 127.0.0.1
2025-10-26 23:22:53,515 - configstream.security_validator - WARNING - [security_validator.py:110] - Suspicious address pattern: 0.0.0.0
2025-10-26 23:22:53,518 - configstream.security_validator - WARNING - [security_validator.py:110] - Suspicious address pattern: 192.168.1.1
2025-10-26 23:22:53,520 - configstream.security_validator - WARNING - [security_validator.py:110] - Suspicious address pattern: 10.0.0.1
2025-10-26 23:22:53,521 - configstream.security_validator - WARNING - [security_validator.py:138] - Private IP range detected: 172.16.0.1
2025-10-26 23:22:53,540 - configstream.security_validator - WARNING - [security_validator.py:92] - Dangerous port detected: 22
2025-10-26 23:22:53,541 - configstream.security_validator - WARNING - [security_validator.py:110] - Suspicious address pattern: localhost
2025-10-26 23:22:53,543 - configstream.security_validator - WARNING - [security_validator.py:370] - Insecure proxy filtered: localhost:22
2025-10-26 23:22:53,544 - configstream.security_validator - INFO - [security_validator.py:378] - Security validation: 2/3 proxies passed
2025-10-26 23:22:53,548 - configstream.security_validator - WARNING - [security_validator.py:110] - Suspicious address pattern: 127.0.0.1
2025-10-26 23:22:53,549 - configstream.security_validator - WARNING - [security_validator.py:370] - Insecure proxy filtered: 127.0.0.1:443
2025-10-26 23:22:53,551 - configstream.security_validator - INFO - [security_validator.py:378] - Security validation: 0/1 proxies passed
2025-10-26 23:22:53,554 - configstream.security_validator - INFO - [security_validator.py:378] - Security validation: 1/1 proxies passed
2025-10-26 23:22:53,557 - configstream.security_validator - INFO - [security_validator.py:378] - Security validation: 0/0 proxies passed
2025-10-26 23:22:53,561 - configstream.security_validator - WARNING - [security_validator.py:92] - Dangerous port detected: 22
2025-10-26 23:22:53,562 - configstream.security_validator - WARNING - [security_validator.py:110] - Suspicious address pattern: localhost
2025-10-26 23:22:53,564 - configstream.security_validator - WARNING - [security_validator.py:370] - Insecure proxy filtered: localhost:22
2025-10-26 23:22:53,565 - configstream.security_validator - WARNING - [security_validator.py:92] - Dangerous port detected: 23
2025-10-26 23:22:53,566 - configstream.security_validator - WARNING - [security_validator.py:110] - Suspicious address pattern: 127.0.0.1
2025-10-26 23:22:53,568 - configstream.security_validator - WARNING - [security_validator.py:370] - Insecure proxy filtered: 127.0.0.1:23
2025-10-26 23:22:53,569 - configstream.security_validator - INFO - [security_validator.py:378] - Security validation: 0/2 proxies passed
2025-10-26 23:22:53,718 - configstream.test_cache - INFO - [test_cache.py:71] - Test cache initialized at /tmp/tmp3jiqk1fc/test.db with WAL mode
2025-10-26 23:22:53,728 - configstream.test_cache - INFO - [test_cache.py:71] - Test cache initialized at /tmp/tmp6ul9zgc1/test.db with WAL mode
2025-10-26 23:22:53,740 - configstream.test_cache - INFO - [test_cache.py:71] - Test cache initialized at /tmp/tmpu7l6q5co/test.db with WAL mode
2025-10-26 23:22:53,745 - configstream.test_cache - INFO - [test_cache.py:71] - Test cache initialized at /tmp/tmpu7l6q5co/test.db with WAL mode
2025-10-26 23:22:53,755 - configstream.test_cache - INFO - [test_cache.py:71] - Test cache initialized at /tmp/tmp8p95329f/test.db with WAL mode
2025-10-26 23:22:53,758 - configstream.test_cache - INFO - [test_cache.py:71] - Test cache initialized at /tmp/tmp8p95329f/test.db with WAL mode
2025-10-26 23:22:53,773 - configstream.test_cache - INFO - [test_cache.py:71] - Test cache initialized at /tmp/tmp1sxxkrl6/test.db with WAL mode
2025-10-26 23:22:53,794 - configstream.test_cache - INFO - [test_cache.py:71] - Test cache initialized at /tmp/tmp5io4xnat/test.db with WAL mode
2025-10-26 23:22:53,815 - configstream.test_cache - INFO - [test_cache.py:71] - Test cache initialized at /tmp/tmpap7btmrt/test.db with WAL mode
2025-10-26 23:22:53,819 - configstream.test_cache - INFO - [test_cache.py:71] - Test cache initialized at /tmp/tmpap7btmrt/test.db with WAL mode
2025-10-26 23:22:53,824 - configstream.test_cache - INFO - [test_cache.py:243] - Cleaned up 1 expired cache entries
2025-10-26 23:22:53,835 - configstream.test_cache - INFO - [test_cache.py:71] - Test cache initialized at /tmp/tmp634o7tmy/test.db with WAL mode
2025-10-26 23:22:53,917 - configstream.testers - ERROR - [testers.py:293] - Proxy test error for vmess://config: Connection error
2025-10-26 23:22:53,926 - configstream.testers - ERROR - [testers.py:293] - Proxy test error for vmess://config: Connection error
2025-10-26 23:23:07,011 - configstream.test_cache - INFO - [test_cache.py:71] - Test cache initialized at /tmp/tmp_tu4w5xz/test.db with WAL mode
2025-10-26 23:24:20,249 - configstream.geoip - INFO - [geoip.py:39] - GeoIP not configured (MAXMIND_LICENSE_KEY not set); skipping.
2025-10-26 23:24:20,263 - configstream.geoip - INFO - [geoip.py:39] - GeoIP not configured (MAXMIND_LICENSE_KEY not set); skipping.
2025-10-26 23:24:20,324 - configstream.geoip - INFO - [geoip.py:39] - GeoIP not configured (MAXMIND_LICENSE_KEY not set); skipping.
2025-10-26 23:24:20,427 - configstream.fetcher - INFO - [fetcher.py:270] - Successfully fetched 4 configs from http://127.0.0.1:45091/proxies (HTTP/1.1, Status: 200, Time: 0.02s)
2025-10-26 23:24:20,459 - configstream.fetcher - WARNING - [fetcher.py:318] - HTTP error fetching http://127.0.0.1:45497/flaky: Server error: 500
2025-10-26 23:24:20,711 - configstream.fetcher - WARNING - [fetcher.py:318] - HTTP error fetching http://127.0.0.1:45497/flaky: Server error: 500
2025-10-26 23:24:21,016 - configstream.fetcher - INFO - [fetcher.py:270] - Successfully fetched 1 configs from http://127.0.0.1:45497/flaky (HTTP/1.1, Status: 200, Time: 0.00s)
2025-10-26 23:24:22,030 - configstream.fetcher - WARNING - [fetcher.py:300] - Timeout fetching http://127.0.0.1:46765/slow (attempt 1/1)
2025-10-26 23:24:22,039 - configstream.fetcher - ERROR - [fetcher.py:345] - Failed to fetch http://127.0.0.1:46765/slow after 1 attempts. Last error: Timeout after 1 seconds
2025-10-26 23:24:26,048 - configstream.fetcher - WARNING - [fetcher.py:287] - Rate limit hit for http://127.0.0.1:37655/limited (host: 127.0.0.1:37655); retrying in 60.5s (attempt 1/1)
2025-10-26 23:25:26,567 - configstream.fetcher - ERROR - [fetcher.py:345] - Failed to fetch http://127.0.0.1:37655/limited after 1 attempts. Last error: Rate limited. Retry after 60.0 seconds
2025-10-26 23:25:26,598 - configstream.fetcher - INFO - [fetcher.py:270] - Successfully fetched 0 configs from http://127.0.0.1:41965/empty (HTTP/1.1, Status: 200, Time: 0.01s)
2025-10-26 23:25:26,627 - configstream.fetcher - WARNING - [fetcher.py:234] - Unexpected content type for http://127.0.0.1:44181/html: text/html; charset=utf-8
2025-10-26 23:25:26,631 - configstream.fetcher - INFO - [fetcher.py:270] - Successfully fetched 0 configs from http://127.0.0.1:44181/html (HTTP/1.1, Status: 200, Time: 0.01s)
2025-10-26 23:25:26,663 - configstream.fetcher - INFO - [fetcher.py:270] - Successfully fetched 1 configs from http://127.0.0.1:45881/redirect (HTTP/1.1, Status: 200, Time: 0.01s)
2025-10-26 23:25:28,580 - httpx - INFO - [_client.py:1740] - HTTP Request: GET http://127.0.0.1:34751/source3 "HTTP/1.1 500 Internal Server Error"
2025-10-26 23:25:28,586 - httpx - INFO - [_client.py:1740] - HTTP Request: GET http://127.0.0.1:34751/source2 "HTTP/1.1 200 OK"
2025-10-26 23:25:28,591 - configstream.fetcher - WARNING - [fetcher.py:318] - HTTP error fetching http://127.0.0.1:34751/source3: Server error: 500
2025-10-26 23:25:28,595 - configstream.fetcher - INFO - [fetcher.py:270] - Successfully fetched 1 configs from http://127.0.0.1:34751/source2 (HTTP/HTTP/1.1, Status: 200, Time: 0.04s)
2025-10-26 23:25:28,600 - httpx - INFO - [_client.py:1740] - HTTP Request: GET http://127.0.0.1:34751/source1 "HTTP/1.1 200 OK"
2025-10-26 23:25:28,603 - configstream.fetcher - INFO - [fetcher.py:270] - Successfully fetched 1 configs from http://127.0.0.1:34751/source1 (HTTP/HTTP/1.1, Status: 200, Time: 0.03s)
2025-10-26 23:25:29,744 - httpx - INFO - [_client.py:1740] - HTTP Request: GET http://127.0.0.1:34751/source3 "HTTP/1.1 500 Internal Server Error"
2025-10-26 23:25:29,747 - configstream.fetcher - WARNING - [fetcher.py:318] - HTTP error fetching http://127.0.0.1:34751/source3: Server error: 500
2025-10-26 23:25:31,769 - httpx - INFO - [_client.py:1740] - HTTP Request: GET http://127.0.0.1:34751/source3 "HTTP/1.1 500 Internal Server Error"
2025-10-26 23:25:31,772 - configstream.fetcher - WARNING - [fetcher.py:318] - HTTP error fetching http://127.0.0.1:34751/source3: Server error: 500
2025-10-26 23:25:31,774 - configstream.fetcher - ERROR - [fetcher.py:345] - Failed to fetch http://127.0.0.1:34751/source3 after 3 attempts. Last error: Server error: 500
2025-10-26 23:25:31,785 - configstream.fetcher - INFO - [fetcher.py:484] - Fetch complete: 2/3 sources successful (0 not modified), 2 total configs collected
2025-10-26 23:25:31,797 - configstream.fetcher - ERROR - [fetcher.py:115] - URL validation failed for not-a-url: Invalid URL format: not-a-url
2025-10-26 23:25:31,799 - configstream.fetcher - ERROR - [fetcher.py:115] - URL validation failed for http://: Invalid URL format: http://
2025-10-26 23:25:31,801 - configstream.fetcher - ERROR - [fetcher.py:115] - URL validation failed for ://missing-scheme: Invalid URL format: ://missing-scheme
2025-10-26 23:25:31,802 - configstream.fetcher - ERROR - [fetcher.py:115] - URL validation failed for http://[invalid: Invalid IPv6 URL
2025-10-26 23:25:31,810 - configstream.fetcher - WARNING - [fetcher.py:327] - HTTP error fetching http://test.com: Connection refused
2025-10-26 23:25:32,895 - configstream.fetcher - WARNING - [fetcher.py:327] - HTTP error fetching http://test.com: Connection refused
2025-10-26 23:25:34,977 - configstream.fetcher - WARNING - [fetcher.py:327] - HTTP error fetching http://test.com: Connection refused
2025-10-26 23:25:34,980 - configstream.fetcher - ERROR - [fetcher.py:345] - Failed to fetch http://test.com after 3 attempts. Last error: HTTP error: Connection refused
2025-10-26 23:25:35,169 - httpx - INFO - [_client.py:1740] - HTTP Request: GET http://127.0.0.1:33229/slow "HTTP/1.1 200 OK"
2025-10-26 23:25:35,173 - configstream.fetcher - INFO - [fetcher.py:270] - Successfully fetched 1 configs from http://127.0.0.1:33229/slow (HTTP/HTTP/1.1, Status: 200, Time: 0.11s)
2025-10-26 23:25:35,188 - httpx - INFO - [_client.py:1740] - HTTP Request: GET http://127.0.0.1:33229/slow "HTTP/1.1 200 OK"
2025-10-26 23:25:35,192 - configstream.fetcher - INFO - [fetcher.py:270] - Successfully fetched 1 configs from http://127.0.0.1:33229/slow (HTTP/HTTP/1.1, Status: 200, Time: 0.11s)
2025-10-26 23:25:35,210 - httpx - INFO - [_client.py:1740] - HTTP Request: GET http://127.0.0.1:33229/slow "HTTP/1.1 200 OK"
2025-10-26 23:25:35,214 - configstream.fetcher - INFO - [fetcher.py:270] - Successfully fetched 1 configs from http://127.0.0.1:33229/slow (HTTP/HTTP/1.1, Status: 200, Time: 0.11s)
2025-10-26 23:25:35,229 - httpx - INFO - [_client.py:1740] - HTTP Request: GET http://127.0.0.1:33229/slow "HTTP/1.1 200 OK"
2025-10-26 23:25:35,233 - configstream.fetcher - INFO - [fetcher.py:270] - Successfully fetched 1 configs from http://127.0.0.1:33229/slow (HTTP/HTTP/1.1, Status: 200, Time: 0.11s)
2025-10-26 23:25:35,249 - httpx - INFO - [_client.py:1740] - HTTP Request: GET http://127.0.0.1:33229/slow "HTTP/1.1 200 OK"
2025-10-26 23:25:35,253 - configstream.fetcher - INFO - [fetcher.py:270] - Successfully fetched 1 configs from http://127.0.0.1:33229/slow (HTTP/HTTP/1.1, Status: 200, Time: 0.11s)
2025-10-26 23:25:35,272 - httpx - INFO - [_client.py:1740] - HTTP Request: GET http://127.0.0.1:33229/slow "HTTP/1.1 200 OK"
2025-10-26 23:25:35,276 - configstream.fetcher - INFO - [fetcher.py:270] - Successfully fetched 1 configs from http://127.0.0.1:33229/slow (HTTP/HTTP/1.1, Status: 200, Time: 0.11s)
2025-10-26 23:25:35,285 - httpx - INFO - [_client.py:1740] - HTTP Request: GET http://127.0.0.1:33229/slow "HTTP/1.1 200 OK"
2025-10-26 23:25:35,288 - configstream.fetcher - INFO - [fetcher.py:270] - Successfully fetched 1 configs from http://127.0.0.1:33229/slow (HTTP/HTTP/1.1, Status: 200, Time: 0.11s)
2025-10-26 23:25:35,305 - httpx - INFO - [_client.py:1740] - HTTP Request: GET http://127.0.0.1:33229/slow "HTTP/1.1 200 OK"
2025-10-26 23:25:35,308 - configstream.fetcher - INFO - [fetcher.py:270] - Successfully fetched 1 configs from http://127.0.0.1:33229/slow (HTTP/HTTP/1.1, Status: 200, Time: 0.11s)
2025-10-26 23:25:35,325 - httpx - INFO - [_client.py:1740] - HTTP Request: GET http://127.0.0.1:33229/slow "HTTP/1.1 200 OK"
2025-10-26 23:25:35,328 - configstream.fetcher - INFO - [fetcher.py:270] - Successfully fetched 1 configs from http://127.0.0.1:33229/slow (HTTP/HTTP/1.1, Status: 200, Time: 0.11s)
2025-10-26 23:25:35,344 - httpx - INFO - [_client.py:1740] - HTTP Request: GET http://127.0.0.1:33229/slow "HTTP/1.1 200 OK"
2025-10-26 23:25:35,348 - configstream.fetcher - INFO - [fetcher.py:270] - Successfully fetched 1 configs from http://127.0.0.1:33229/slow (HTTP/HTTP/1.1, Status: 200, Time: 0.11s)
2025-10-26 23:25:35,360 - configstream.fetcher - INFO - [fetcher.py:484] - Fetch complete: 1/10 sources successful (0 not modified), 1 total configs collected
2025-10-26 23:25:35,484 - httpx - INFO - [_client.py:1740] - HTTP Request: GET http://127.0.0.1:42733/source_18 "HTTP/1.1 200 OK"
2025-10-26 23:25:35,487 - configstream.fetcher - INFO - [fetcher.py:270] - Successfully fetched 1 configs from http://127.0.0.1:42733/source_18 (HTTP/HTTP/1.1, Status: 200, Time: 0.05s)
2025-10-26 23:25:35,494 - httpx - INFO - [_client.py:1740] - HTTP Request: GET http://127.0.0.1:42733/source_6 "HTTP/1.1 200 OK"
2025-10-26 23:25:35,496 - configstream.fetcher - INFO - [fetcher.py:270] - Successfully fetched 1 configs from http://127.0.0.1:42733/source_6 (HTTP/HTTP/1.1, Status: 200, Time: 0.04s)
2025-10-26 23:25:35,533 - httpx - INFO - [_client.py:1740] - HTTP Request: GET http://127.0.0.1:42733/source_7 "HTTP/1.1 200 OK"
2025-10-26 23:25:35,536 - configstream.fetcher - INFO - [fetcher.py:270] - Successfully fetched 1 configs from http://127.0.0.1:42733/source_7 (HTTP/HTTP/1.1, Status: 200, Time: 0.04s)
2025-10-26 23:25:35,539 - httpx - INFO - [_client.py:1740] - HTTP Request: GET http://127.0.0.1:42733/source_8 "HTTP/1.1 200 OK"
2025-10-26 23:25:35,542 - configstream.fetcher - INFO - [fetcher.py:270] - Successfully fetched 1 configs from http://127.0.0.1:42733/source_8 (HTTP/HTTP/1.1, Status: 200, Time: 0.06s)
2025-10-26 23:25:35,559 - httpx - INFO - [_client.py:1740] - HTTP Request: GET http://127.0.0.1:42733/source_4 "HTTP/1.1 200 OK"
2025-10-26 23:25:35,565 - configstream.fetcher - INFO - [fetcher.py:270] - Successfully fetched 1 configs from http://127.0.0.1:42733/source_4 (HTTP/HTTP/1.1, Status: 200, Time: 0.05s)
2025-10-26 23:25:35,584 - httpx - INFO - [_client.py:1740] - HTTP Request: GET http://127.0.0.1:42733/source_10 "HTTP/1.1 200 OK"
2025-10-26 23:25:35,587 - configstream.fetcher - INFO - [fetcher.py:270] - Successfully fetched 1 configs from http://127.0.0.1:42733/source_10 (HTTP/HTTP/1.1, Status: 200, Time: 0.04s)
2025-10-26 23:25:35,596 - httpx - INFO - [_client.py:1740] - HTTP Request: GET http://127.0.0.1:42733/source_16 "HTTP/1.1 200 OK"
2025-10-26 23:25:35,599 - configstream.fetcher - INFO - [fetcher.py:270] - Successfully fetched 1 configs from http://127.0.0.1:42733/source_16 (HTTP/HTTP/1.1, Status: 200, Time: 0.04s)
2025-10-26 23:25:35,623 - httpx - INFO - [_client.py:1740] - HTTP Request: GET http://127.0.0.1:42733/source_5 "HTTP/1.1 200 OK"
2025-10-26 23:25:35,626 - configstream.fetcher - INFO - [fetcher.py:270] - Successfully fetched 1 configs from http://127.0.0.1:42733/source_5 (HTTP/HTTP/1.1, Status: 200, Time: 0.05s)
2025-10-26 23:25:35,643 - httpx - INFO - [_client.py:1740] - HTTP Request: GET http://127.0.0.1:42733/source_11 "HTTP/1.1 200 OK"
2025-10-26 23:25:35,646 - httpx - INFO - [_client.py:1740] - HTTP Request: GET http://127.0.0.1:42733/source_3 "HTTP/1.1 200 OK"
2025-10-26 23:25:35,648 - configstream.fetcher - INFO - [fetcher.py:270] - Successfully fetched 1 configs from http://127.0.0.1:42733/source_11 (HTTP/HTTP/1.1, Status: 200, Time: 0.03s)
2025-10-26 23:25:35,651 - configstream.fetcher - INFO - [fetcher.py:270] - Successfully fetched 1 configs from http://127.0.0.1:42733/source_3 (HTTP/HTTP/1.1, Status: 200, Time: 0.05s)
2025-10-26 23:25:35,667 - httpx - INFO - [_client.py:1740] - HTTP Request: GET http://127.0.0.1:42733/source_15 "HTTP/1.1 200 OK"
2025-10-26 23:25:35,670 - configstream.fetcher - INFO - [fetcher.py:270] - Successfully fetched 1 configs from http://127.0.0.1:42733/source_15 (HTTP/HTTP/1.1, Status: 200, Time: 0.03s)
2025-10-26 23:25:35,707 - httpx - INFO - [_client.py:1740] - HTTP Request: GET http://127.0.0.1:42733/source_17 "HTTP/1.1 200 OK"
2025-10-26 23:25:35,710 - configstream.fetcher - INFO - [fetcher.py:270] - Successfully fetched 1 configs from http://127.0.0.1:42733/source_17 (HTTP/HTTP/1.1, Status: 200, Time: 0.03s)
2025-10-26 23:25:35,713 - httpx - INFO - [_client.py:1740] - HTTP Request: GET http://127.0.0.1:42733/source_14 "HTTP/1.1 200 OK"
2025-10-26 23:25:35,716 - configstream.fetcher - INFO - [fetcher.py:270] - Successfully fetched 1 configs from http://127.0.0.1:42733/source_14 (HTTP/HTTP/1.1, Status: 200, Time: 0.06s)
2025-10-26 23:25:35,722 - httpx - INFO - [_client.py:1740] - HTTP Request: GET http://127.0.0.1:42733/source_12 "HTTP/1.1 200 OK"
2025-10-26 23:25:35,726 - configstream.fetcher - INFO - [fetcher.py:270] - Successfully fetched 1 configs from http://127.0.0.1:42733/source_12 (HTTP/HTTP/1.1, Status: 200, Time: 0.03s)
2025-10-26 23:25:35,754 - httpx - INFO - [_client.py:1740] - HTTP Request: GET http://127.0.0.1:42733/source_0 "HTTP/1.1 200 OK"
2025-10-26 23:25:35,757 - configstream.fetcher - INFO - [fetcher.py:270] - Successfully fetched 1 configs from http://127.0.0.1:42733/source_0 (HTTP/HTTP/1.1, Status: 200, Time: 0.04s)
2025-10-26 23:25:35,769 - httpx - INFO - [_client.py:1740] - HTTP Request: GET http://127.0.0.1:42733/source_19 "HTTP/1.1 200 OK"
2025-10-26 23:25:35,772 - configstream.fetcher - INFO - [fetcher.py:270] - Successfully fetched 1 configs from http://127.0.0.1:42733/source_19 (HTTP/HTTP/1.1, Status: 200, Time: 0.03s)
2025-10-26 23:25:35,782 - httpx - INFO - [_client.py:1740] - HTTP Request: GET http://127.0.0.1:42733/source_9 "HTTP/1.1 200 OK"
2025-10-26 23:25:35,784 - configstream.fetcher - INFO - [fetcher.py:270] - Successfully fetched 1 configs from http://127.0.0.1:42733/source_9 (HTTP/HTTP/1.1, Status: 200, Time: 0.03s)
2025-10-26 23:25:35,815 - httpx - INFO - [_client.py:1740] - HTTP Request: GET http://127.0.0.1:42733/source_2 "HTTP/1.1 200 OK"
2025-10-26 23:25:35,818 - configstream.fetcher - INFO - [fetcher.py:270] - Successfully fetched 1 configs from http://127.0.0.1:42733/source_2 (HTTP/HTTP/1.1, Status: 200, Time: 0.02s)
2025-10-26 23:25:35,824 - httpx - INFO - [_client.py:1740] - HTTP Request: GET http://127.0.0.1:42733/source_13 "HTTP/1.1 200 OK"
2025-10-26 23:25:35,827 - configstream.fetcher - INFO - [fetcher.py:270] - Successfully fetched 1 configs from http://127.0.0.1:42733/source_13 (HTTP/HTTP/1.1, Status: 200, Time: 0.05s)
2025-10-26 23:25:35,848 - httpx - INFO - [_client.py:1740] - HTTP Request: GET http://127.0.0.1:42733/source_1 "HTTP/1.1 200 OK"
2025-10-26 23:25:35,851 - configstream.fetcher - INFO - [fetcher.py:270] - Successfully fetched 1 configs from http://127.0.0.1:42733/source_1 (HTTP/HTTP/1.1, Status: 200, Time: 0.03s)
2025-10-26 23:25:35,862 - configstream.fetcher - INFO - [fetcher.py:484] - Fetch complete: 20/20 sources successful (0 not modified), 20 total configs collected
2025-10-26 23:25:35,943 - httpx - INFO - [_client.py:1740] - HTTP Request: GET http://127.0.0.1:38293/s2 "HTTP/1.1 200 OK"
2025-10-26 23:25:35,946 - configstream.fetcher - INFO - [fetcher.py:270] - Successfully fetched 1 configs from http://127.0.0.1:38293/s2 (HTTP/HTTP/1.1, Status: 200, Time: 0.01s)
2025-10-26 23:25:35,960 - httpx - INFO - [_client.py:1740] - HTTP Request: GET http://127.0.0.1:38293/s1 "HTTP/1.1 200 OK"
2025-10-26 23:25:35,963 - configstream.fetcher - INFO - [fetcher.py:270] - Successfully fetched 2 configs from http://127.0.0.1:38293/s1 (HTTP/HTTP/1.1, Status: 200, Time: 0.01s)
2025-10-26 23:25:35,971 - configstream.fetcher - INFO - [fetcher.py:484] - Fetch complete: 2/2 sources successful (0 not modified), 3 total configs collected
2025-10-26 23:25:36,050 - httpx - INFO - [_client.py:1740] - HTTP Request: GET http://127.0.0.1:36389/many "HTTP/1.1 200 OK"
2025-10-26 23:25:36,053 - configstream.fetcher - INFO - [fetcher.py:270] - Successfully fetched 100 configs from http://127.0.0.1:36389/many (HTTP/HTTP/1.1, Status: 200, Time: 0.01s)
2025-10-26 23:25:36,062 - configstream.fetcher - INFO - [fetcher.py:484] - Fetch complete: 1/1 sources successful (0 not modified), 100 total configs collected
2025-10-26 23:25:36,090 - configstream.pipeline - WARNING - [pipeline.py:103] - Skipping invalid source 'ftp://invalid.com': Unsupported URL scheme: ftp
2025-10-26 23:25:36,093 - configstream.pipeline - WARNING - [pipeline.py:103] - Skipping invalid source '': Source is empty
2025-10-26 23:25:36,117 - configstream.pipeline - INFO - [pipeline.py:217] - No usable configurations found in http://example.com/source
2025-10-26 23:25:36,127 - configstream.geoip - INFO - [geoip.py:39] - GeoIP not configured (MAXMIND_LICENSE_KEY not set); skipping.
2025-10-26 23:25:36,129 - configstream.pipeline - INFO - [pipeline.py:279] - Starting pipeline with 1 sources and 0 supplied proxies
2025-10-26 23:25:36,131 - configstream.pipeline - INFO - [pipeline.py:353] - PIPELINE: Fetched 1 raw proxy configs.
2025-10-26 23:25:36,133 - configstream.pipeline - INFO - [pipeline.py:372] - PIPELINE: Prepared 1 unique configs for sequential processing.
2025-10-26 23:25:36,134 - configstream.pipeline - INFO - [pipeline.py:394] - Using effective test timeout of 10.00s
2025-10-26 23:25:36,138 - configstream.test_cache - INFO - [test_cache.py:71] - Test cache initialized at data/test_cache.db with WAL mode
2025-10-26 23:25:36,140 - configstream.pipeline - INFO - [pipeline.py:398] - Test cache initialized: {'total_entries': 0, 'valid_entries': 0, 'expired_entries': 0, 'average_health_score': 0.0, 'ttl_seconds': 86400}
2025-10-26 23:25:36,154 - configstream.security_validator - INFO - [security_validator.py:378] - Security validation: 1/1 proxies passed
2025-10-26 23:25:36,157 - configstream.pipeline - WARNING - [pipeline.py:452] - GeoIP database not found at data/GeoLite2-City.mmdb
2025-10-26 23:25:36,160 - configstream.pipeline - INFO - [pipeline.py:825] - Filtered phase-1 to 1 proxies with latency <= 5000ms
2025-10-26 23:25:36,173 - configstream.pipeline - INFO - [pipeline.py:643] - Generated 3 categorized output files
2025-10-26 23:25:36,175 - configstream.pipeline - INFO - [pipeline.py:905] - Pipeline completed successfully in 0.0 seconds
2025-10-26 23:25:36,184 - configstream.pipeline - ERROR - [pipeline.py:265] - No sources provided and no proxies supplied for retest
2025-10-26 23:25:36,193 - configstream.geoip - INFO - [geoip.py:39] - GeoIP not configured (MAXMIND_LICENSE_KEY not set); skipping.
2025-10-26 23:25:36,195 - configstream.pipeline - INFO - [pipeline.py:279] - Starting pipeline with 1 sources and 0 supplied proxies
2025-10-26 23:25:36,197 - configstream.pipeline - INFO - [pipeline.py:353] - PIPELINE: Fetched 1 raw proxy configs.
2025-10-26 23:25:36,199 - configstream.pipeline - INFO - [pipeline.py:372] - PIPELINE: Prepared 1 unique configs for sequential processing.
2025-10-26 23:25:36,200 - configstream.pipeline - INFO - [pipeline.py:394] - Using effective test timeout of 10.00s
2025-10-26 23:25:36,202 - configstream.test_cache - INFO - [test_cache.py:71] - Test cache initialized at data/test_cache.db with WAL mode
2025-10-26 23:25:36,204 - configstream.pipeline - INFO - [pipeline.py:398] - Test cache initialized: {'total_entries': 0, 'valid_entries': 0, 'expired_entries': 0, 'average_health_score': 0.0, 'ttl_seconds': 86400}
2025-10-26 23:25:36,206 - configstream.security_validator - INFO - [security_validator.py:378] - Security validation: 1/1 proxies passed
2025-10-26 23:25:36,209 - configstream.pipeline - WARNING - [pipeline.py:452] - GeoIP database not found at data/GeoLite2-City.mmdb
2025-10-26 23:25:36,211 - configstream.pipeline - INFO - [pipeline.py:825] - Filtered phase-1 to 0 proxies with latency <= 5000ms
2025-10-26 23:25:36,212 - configstream.pipeline - WARNING - [pipeline.py:852] - No working proxies detected in phase-1; keeping tested proxies as fallback
2025-10-26 23:25:36,221 - configstream.pipeline - INFO - [pipeline.py:643] - Generated 2 categorized output files
2025-10-26 23:25:36,223 - configstream.pipeline - WARNING - [pipeline.py:899] - No proxies passed all filters across all phases
2025-10-26 23:25:36,225 - configstream.pipeline - INFO - [pipeline.py:905] - Pipeline completed successfully in 0.0 seconds
2025-10-26 23:25:36,285 - configstream.geoip - INFO - [geoip.py:39] - GeoIP not configured (MAXMIND_LICENSE_KEY not set); skipping.
2025-10-26 23:25:36,287 - configstream.pipeline - INFO - [pipeline.py:279] - Starting pipeline with 1 sources and 0 supplied proxies
2025-10-26 23:25:36,289 - configstream.pipeline - INFO - [pipeline.py:353] - PIPELINE: Fetched 3 raw proxy configs.
2025-10-26 23:25:36,291 - configstream.pipeline - INFO - [pipeline.py:372] - PIPELINE: Prepared 3 unique configs for sequential processing.
2025-10-26 23:25:36,292 - configstream.pipeline - INFO - [pipeline.py:394] - Using effective test timeout of 10.00s
2025-10-26 23:25:36,295 - configstream.test_cache - INFO - [test_cache.py:71] - Test cache initialized at data/test_cache.db with WAL mode
2025-10-26 23:25:36,297 - configstream.pipeline - INFO - [pipeline.py:398] - Test cache initialized: {'total_entries': 0, 'valid_entries': 0, 'expired_entries': 0, 'average_health_score': 0.0, 'ttl_seconds': 86400}
2025-10-26 23:25:36,299 - configstream.security_validator - INFO - [security_validator.py:378] - Security validation: 3/3 proxies passed
2025-10-26 23:25:36,301 - configstream.pipeline - INFO - [pipeline.py:771] - Limiting phase-1 to 2 proxies to respect max_proxies
2025-10-26 23:25:36,304 - configstream.pipeline - WARNING - [pipeline.py:452] - GeoIP database not found at data/GeoLite2-City.mmdb
2025-10-26 23:25:36,306 - configstream.pipeline - INFO - [pipeline.py:825] - Filtered phase-1 to 2 proxies with latency <= 5000ms
2025-10-26 23:25:36,322 - configstream.pipeline - INFO - [pipeline.py:643] - Generated 3 categorized output files
2025-10-26 23:25:36,324 - configstream.pipeline - INFO - [pipeline.py:905] - Pipeline completed successfully in 0.1 seconds
2025-10-26 23:25:36,335 - configstream.geoip - INFO - [geoip.py:39] - GeoIP not configured (MAXMIND_LICENSE_KEY not set); skipping.
2025-10-26 23:25:36,336 - configstream.pipeline - INFO - [pipeline.py:279] - Starting pipeline with 0 sources and 3 supplied proxies
2025-10-26 23:25:36,338 - configstream.pipeline - INFO - [pipeline.py:353] - PIPELINE: Fetched 0 raw proxy configs.
2025-10-26 23:25:36,339 - configstream.pipeline - INFO - [pipeline.py:372] - PIPELINE: Prepared 0 unique configs for sequential processing.
2025-10-26 23:25:36,341 - configstream.pipeline - INFO - [pipeline.py:381] - Using 3 supplied proxies
2025-10-26 23:25:36,343 - configstream.pipeline - INFO - [pipeline.py:394] - Using effective test timeout of 1.00s
2025-10-26 23:25:36,345 - configstream.test_cache - INFO - [test_cache.py:71] - Test cache initialized at data/test_cache.db with WAL mode
2025-10-26 23:25:36,347 - configstream.pipeline - INFO - [pipeline.py:398] - Test cache initialized: {'total_entries': 0, 'valid_entries': 0, 'expired_entries': 0, 'average_health_score': 0.0, 'ttl_seconds': 86400}
2025-10-26 23:25:36,349 - configstream.pipeline - WARNING - [pipeline.py:452] - GeoIP database not found at data/GeoLite2-City.mmdb
2025-10-26 23:25:36,352 - configstream.pipeline - INFO - [pipeline.py:798] - Filtered phase-1 to 2 proxies in US
2025-10-26 23:25:36,353 - configstream.pipeline - INFO - [pipeline.py:811] - Filtered phase-1 to 2 proxies with latency >= 50ms
2025-10-26 23:25:36,355 - configstream.pipeline - INFO - [pipeline.py:825] - Filtered phase-1 to 1 proxies with latency <= 1000ms
2025-10-26 23:25:36,369 - configstream.pipeline - INFO - [pipeline.py:643] - Generated 5 categorized output files
2025-10-26 23:25:36,371 - configstream.pipeline - INFO - [pipeline.py:905] - Pipeline completed successfully in 0.0 seconds
2025-10-26 23:25:36,381 - configstream.geoip - INFO - [geoip.py:39] - GeoIP not configured (MAXMIND_LICENSE_KEY not set); skipping.
2025-10-26 23:25:36,383 - configstream.pipeline - INFO - [pipeline.py:279] - Starting pipeline with 1 sources and 0 supplied proxies
2025-10-26 23:25:36,424 - configstream.pipeline - INFO - [pipeline.py:353] - PIPELINE: Fetched 1 raw proxy configs.
2025-10-26 23:25:36,426 - configstream.pipeline - INFO - [pipeline.py:372] - PIPELINE: Prepared 1 unique configs for sequential processing.
2025-10-26 23:25:36,428 - configstream.pipeline - INFO - [pipeline.py:394] - Using effective test timeout of 10.00s
2025-10-26 23:25:36,430 - configstream.test_cache - INFO - [test_cache.py:71] - Test cache initialized at data/test_cache.db with WAL mode
2025-10-26 23:25:36,432 - configstream.pipeline - INFO - [pipeline.py:398] - Test cache initialized: {'total_entries': 0, 'valid_entries': 0, 'expired_entries': 0, 'average_health_score': 0.0, 'ttl_seconds': 86400}
2025-10-26 23:25:36,434 - configstream.security_validator - INFO - [security_validator.py:378] - Security validation: 1/1 proxies passed
2025-10-26 23:25:36,437 - configstream.pipeline - WARNING - [pipeline.py:452] - GeoIP database not found at data/GeoLite2-City.mmdb
2025-10-26 23:25:36,439 - configstream.pipeline - INFO - [pipeline.py:825] - Filtered phase-1 to 1 proxies with latency <= 5000ms
2025-10-26 23:25:36,450 - configstream.pipeline - INFO - [pipeline.py:643] - Generated 3 categorized output files
2025-10-26 23:25:36,452 - configstream.pipeline - INFO - [pipeline.py:905] - Pipeline completed successfully in 0.1 seconds
2025-10-26 23:25:36,502 - configstream.pipeline - WARNING - [pipeline.py:340] - Failed to fetch http://failing-remote.com/source: Fetch failed!
2025-10-26 23:25:36,505 - configstream.pipeline - ERROR - [pipeline.py:884] - No configurations could be parsed
2025-10-26 23:25:36,514 - configstream.geoip - INFO - [geoip.py:39] - GeoIP not configured (MAXMIND_LICENSE_KEY not set); skipping.
2025-10-26 23:25:36,516 - configstream.pipeline - INFO - [pipeline.py:279] - Starting pipeline with 1 sources and 0 supplied proxies
2025-10-26 23:25:36,518 - configstream.pipeline - INFO - [pipeline.py:353] - PIPELINE: Fetched 0 raw proxy configs.
2025-10-26 23:25:36,519 - configstream.pipeline - INFO - [pipeline.py:372] - PIPELINE: Prepared 0 unique configs for sequential processing.
2025-10-26 23:25:36,521 - configstream.pipeline - INFO - [pipeline.py:394] - Using effective test timeout of 10.00s
2025-10-26 23:25:36,523 - configstream.test_cache - INFO - [test_cache.py:71] - Test cache initialized at data/test_cache.db with WAL mode
2025-10-26 23:25:36,525 - configstream.pipeline - INFO - [pipeline.py:398] - Test cache initialized: {'total_entries': 0, 'valid_entries': 0, 'expired_entries': 0, 'average_health_score': 0.0, 'ttl_seconds': 86400}
2025-10-26 23:25:36,527 - configstream.pipeline - ERROR - [pipeline.py:884] - No configurations could be parsed
2025-10-26 23:25:36,536 - configstream.pipeline - ERROR - [pipeline.py:265] - No sources provided and no proxies supplied for retest
2025-10-26 23:25:36,545 - configstream.geoip - INFO - [geoip.py:39] - GeoIP not configured (MAXMIND_LICENSE_KEY not set); skipping.
2025-10-26 23:25:36,547 - configstream.pipeline - INFO - [pipeline.py:279] - Starting pipeline with 1 sources and 0 supplied proxies
2025-10-26 23:25:36,549 - configstream.pipeline - INFO - [pipeline.py:353] - PIPELINE: Fetched 1 raw proxy configs.
2025-10-26 23:25:36,550 - configstream.pipeline - INFO - [pipeline.py:372] - PIPELINE: Prepared 1 unique configs for sequential processing.
2025-10-26 23:25:36,552 - configstream.pipeline - INFO - [pipeline.py:394] - Using effective test timeout of 10.00s
2025-10-26 23:25:36,554 - configstream.test_cache - INFO - [test_cache.py:71] - Test cache initialized at data/test_cache.db with WAL mode
2025-10-26 23:25:36,556 - configstream.pipeline - INFO - [pipeline.py:398] - Test cache initialized: {'total_entries': 0, 'valid_entries': 0, 'expired_entries': 0, 'average_health_score': 0.0, 'ttl_seconds': 86400}
2025-10-26 23:25:36,558 - configstream.security_validator - INFO - [security_validator.py:378] - Security validation: 1/1 proxies passed
2025-10-26 23:25:36,560 - configstream.pipeline - WARNING - [pipeline.py:452] - GeoIP database not found at data/GeoLite2-City.mmdb
2025-10-26 23:25:36,562 - configstream.pipeline - INFO - [pipeline.py:825] - Filtered phase-1 to 1 proxies with latency <= 5000ms
2025-10-26 23:25:36,573 - configstream.pipeline - INFO - [pipeline.py:643] - Generated 3 categorized output files
2025-10-26 23:25:36,575 - configstream.pipeline - INFO - [pipeline.py:905] - Pipeline completed successfully in 0.0 seconds
2025-10-26 23:25:36,585 - configstream.geoip - INFO - [geoip.py:39] - GeoIP not configured (MAXMIND_LICENSE_KEY not set); skipping.
2025-10-26 23:25:36,587 - configstream.pipeline - INFO - [pipeline.py:279] - Starting pipeline with 1 sources and 0 supplied proxies
2025-10-26 23:25:36,589 - configstream.pipeline - INFO - [pipeline.py:353] - PIPELINE: Fetched 1 raw proxy configs.
2025-10-26 23:25:36,590 - configstream.pipeline - INFO - [pipeline.py:372] - PIPELINE: Prepared 1 unique configs for sequential processing.
2025-10-26 23:25:36,592 - configstream.pipeline - INFO - [pipeline.py:394] - Using effective test timeout of 10.00s
2025-10-26 23:25:36,594 - configstream.test_cache - INFO - [test_cache.py:71] - Test cache initialized at data/test_cache.db with WAL mode
2025-10-26 23:25:36,596 - configstream.pipeline - INFO - [pipeline.py:398] - Test cache initialized: {'total_entries': 0, 'valid_entries': 0, 'expired_entries': 0, 'average_health_score': 0.0, 'ttl_seconds': 86400}
2025-10-26 23:25:36,598 - configstream.security_validator - WARNING - [security_validator.py:110] - Suspicious address pattern: 127.0.0.1
2025-10-26 23:25:36,600 - configstream.security_validator - WARNING - [security_validator.py:370] - Insecure proxy filtered: 127.0.0.1:443
2025-10-26 23:25:36,601 - configstream.security_validator - INFO - [security_validator.py:378] - Security validation: 0/1 proxies passed
2025-10-26 23:25:36,603 - configstream.pipeline - INFO - [pipeline.py:712] - 1 insecure proxies were filtered out
2025-10-26 23:25:36,605 - configstream.pipeline - ERROR - [pipeline.py:884] - No configurations could be parsed or all were deemed insecure
2025-10-26 23:25:36,631 - configstream.geoip - INFO - [geoip.py:39] - GeoIP not configured (MAXMIND_LICENSE_KEY not set); skipping.
2025-10-26 23:25:36,634 - configstream.pipeline - INFO - [pipeline.py:279] - Starting pipeline with 1 sources and 0 supplied proxies
2025-10-26 23:25:36,682 - configstream.pipeline - INFO - [pipeline.py:353] - PIPELINE: Fetched 1010 raw proxy configs.
2025-10-26 23:25:36,686 - configstream.pipeline - INFO - [pipeline.py:372] - PIPELINE: Prepared 1010 unique configs for sequential processing.
2025-10-26 23:25:36,688 - configstream.pipeline - INFO - [pipeline.py:394] - Using effective test timeout of 10.00s
2025-10-26 23:25:36,691 - configstream.test_cache - INFO - [test_cache.py:71] - Test cache initialized at data/test_cache.db with WAL mode
2025-10-26 23:25:36,694 - configstream.pipeline - INFO - [pipeline.py:398] - Test cache initialized: {'total_entries': 0, 'valid_entries': 0, 'expired_entries': 0, 'average_health_score': 0.0, 'ttl_seconds': 86400}
2025-10-26 23:25:36,969 - configstream.security_validator - INFO - [security_validator.py:378] - Security validation: 1010/1010 proxies passed
2025-10-26 23:25:37,032 - configstream.pipeline - INFO - [pipeline.py:423] - Testing batch 1/2 (1000 proxies) for phase-1
2025-10-26 23:25:37,148 - configstream.pipeline - INFO - [pipeline.py:423] - Testing batch 2/2 (10 proxies) for phase-1
2025-10-26 23:25:37,152 - configstream.pipeline - WARNING - [pipeline.py:452] - GeoIP database not found at data/GeoLite2-City.mmdb
2025-10-26 23:25:37,250 - configstream.pipeline - INFO - [pipeline.py:825] - Filtered phase-1 to 1010 proxies with latency <= 5000ms
2025-10-26 23:25:39,135 - configstream.pipeline - INFO - [pipeline.py:643] - Generated 4 categorized output files
2025-10-26 23:25:39,138 - configstream.pipeline - INFO - [pipeline.py:905] - Pipeline completed successfully in 2.5 seconds
2025-10-26 23:25:39,471 - configstream.async_file_ops - ERROR - [async_file_ops.py:103] - File not found: /tmp/pytest-of-jules/pytest-17/test_read_file_async_not_found0/does_not_exist.txt
2025-10-26 23:25:39,499 - configstream.async_file_ops - INFO - [async_file_ops.py:239] - Read 10/10 files successfully
2025-10-26 23:25:39,508 - configstream.async_file_ops - WARNING - [async_file_ops.py:227] - Failed to read /tmp/pytest-of-jules/pytest-17/test_read_multiple_files_handl0/missing.txt: [Errno 2] No such file or directory: '/tmp/pytest-of-jules/pytest-17/test_read_multiple_files_handl0/missing.txt'
2025-10-26 23:25:39,511 - configstream.async_file_ops - INFO - [async_file_ops.py:239] - Read 2/3 files successfully
2025-10-26 23:25:39,830 - configstream.async_file_ops - INFO - [async_file_ops.py:239] - Read 100/100 files successfully
2025-10-26 23:25:39,843 - configstream.test_cache - INFO - [test_cache.py:71] - Test cache initialized at /tmp/pytest-of-jules/pytest-17/test_warm_cache_prioritizes_hi0/test_cache.db with WAL mode
2025-10-26 23:25:39,968 - configstream.test_cache - INFO - [test_cache.py:71] - Test cache initialized at /tmp/pytest-of-jules/pytest-17/test_warm_cache_with_no_cached0/test_cache.db with WAL mode
2025-10-26 23:25:39,981 - configstream.test_cache - INFO - [test_cache.py:71] - Test cache initialized at /tmp/pytest-of-jules/pytest-17/test_warm_cache_with_all_cache0/test_cache.db with WAL mode
2025-10-26 23:25:40,172 - configstream.test_cache - INFO - [test_cache.py:71] - Test cache initialized at /tmp/pytest-of-jules/pytest-17/test_warm_cache_with_empty_lis0/test_cache.db with WAL mode
2025-10-26 23:25:40,189 - configstream.test_cache - INFO - [test_cache.py:71] - Test cache initialized at /tmp/pytest-of-jules/pytest-17/test_warm_cache_ordering_corre0/test_cache.db with WAL mode
2025-10-26 23:25:40,412 - configstream.fetcher - WARNING - [fetcher.py:318] - HTTP error fetching http://example.com: Server error: 500
2025-10-26 23:25:40,718 - configstream.fetcher - WARNING - [fetcher.py:318] - HTTP error fetching http://example.com: Server error: 502
2025-10-26 23:25:41,037 - configstream.fetcher - WARNING - [fetcher.py:322] - HTTP error fetching http://example.com: test error
2025-10-26 23:25:41,040 - configstream.fetcher - ERROR - [fetcher.py:345] - Failed to fetch http://example.com after 3 attempts. Last error: HTTP error: test error
2025-10-26 23:25:41,048 - configstream.fetcher - WARNING - [fetcher.py:234] - Unexpected content type for http://example.com: text/html
2025-10-26 23:25:41,050 - configstream.fetcher - INFO - [fetcher.py:270] - Successfully fetched 2 configs from http://example.com (HTTP/<AsyncMock name='mock.get().http_version' id='139922131518768'>, Status: 200, Time: 0.00s)
2025-10-26 23:25:41,058 - configstream.fetcher - WARNING - [fetcher.py:287] - Rate limit hit for http://example.com (host: example.com); retrying in 0.4s (attempt 1/2)
2025-10-26 23:25:41,703 - configstream.fetcher - INFO - [fetcher.py:270] - Successfully fetched 1 configs from http://example.com (HTTP/<AsyncMock name='mock.http_version' id='139922130860560'>, Status: 200, Time: 0.00s)
2025-10-26 23:25:41,711 - configstream.fetcher - WARNING - [fetcher.py:309] - Timeout fetching http://example.com (attempt 1/1)
2025-10-26 23:25:41,713 - configstream.fetcher - ERROR - [fetcher.py:345] - Failed to fetch http://example.com after 1 attempts. Last error: Timeout after 30 seconds
2025-10-26 23:25:41,720 - configstream.fetcher - ERROR - [fetcher.py:115] - URL validation failed for invalid-url: Invalid URL format: invalid-url
2025-10-26 23:25:41,770 - configstream.fetcher - ERROR - [fetcher.py:470] - Unhandled exception for http://example.com/source1: Unhandled test exception
2025-10-26 23:25:41,779 - configstream.fetcher - INFO - [fetcher.py:484] - Fetch complete: 1/2 sources successful (0 not modified), 1 total configs collected
2025-10-26 23:25:41,818 - configstream.test_cache - INFO - [test_cache.py:71] - Test cache initialized at /tmp/tmp90a2h2k9/test.db with WAL mode
2025-10-26 23:25:41,936 - httpx - INFO - [_client.py:1740] - HTTP Request: GET http://ip-api.com/json/192.168.1.1?fields=status,country,countryCode,city,as "HTTP/1.1 200 OK"
2025-10-26 23:25:41,950 - configstream.test_cache - INFO - [test_cache.py:71] - Test cache initialized at /tmp/tmp3vqju2l2/test.db with WAL mode
2025-10-26 23:25:41,965 - configstream.test_cache - INFO - [test_cache.py:71] - Test cache initialized at /tmp/tmpaklepmmy/cache.db with WAL mode
2025-10-26 23:25:41,973 - configstream.security_validator - WARNING - [security_validator.py:334] - Security validation is running in leniency mode. No proxies will be filtered.
2025-10-26 23:25:41,974 - configstream.security_validator - INFO - [security_validator.py:354] - Security validation (leniency mode): Detected 0 insecure proxies, but not filtering.
2025-10-26 23:25:41,976 - configstream.security_validator - WARNING - [security_validator.py:334] - Security validation is running in leniency mode. No proxies will be filtered.
2025-10-26 23:25:41,977 - configstream.security_validator - INFO - [security_validator.py:354] - Security validation (leniency mode): Detected 0 insecure proxies, but not filtering.
2025-10-26 23:25:42,063 - httpx - INFO - [_client.py:1740] - HTTP Request: GET http://ip-api.com/json/127.0.0.1?fields=status,country,countryCode,city,as "HTTP/1.1 200 OK"
2025-10-26 23:25:42,146 - httpx - INFO - [_client.py:1740] - HTTP Request: GET http://ip-api.com/json/::1?fields=status,country,countryCode,city,as "HTTP/1.1 200 OK"
2025-10-26 23:25:42,239 - httpx - INFO - [_client.py:1740] - HTTP Request: GET http://ip-api.com/json/unknown.test?fields=status,country,countryCode,city,as "HTTP/1.1 200 OK"
2025-10-26 23:25:42,258 - configstream.test_cache - INFO - [test_cache.py:71] - Test cache initialized at /tmp/tmpf1lb_u8s/test.db with WAL mode
2025-10-26 23:25:43,368 - configstream.test_cache - INFO - [test_cache.py:243] - Cleaned up 1 expired cache entries
2025-10-26 23:25:43,381 - configstream.geoip - INFO - [geoip.py:39] - GeoIP not configured (MAXMIND_LICENSE_KEY not set); skipping.
2025-10-26 23:25:43,392 - configstream.geoip - INFO - [geoip.py:49] - Downloading GeoLite2-Country...
2025-10-26 23:25:43,394 - configstream.geoip - INFO - [geoip.py:51] - GeoLite2-Country downloaded successfully
2025-10-26 23:25:43,396 - configstream.geoip - INFO - [geoip.py:49] - Downloading GeoLite2-City...
2025-10-26 23:25:43,397 - configstream.geoip - INFO - [geoip.py:51] - GeoLite2-City downloaded successfully
2025-10-26 23:25:43,407 - configstream.geoip - INFO - [geoip.py:49] - Downloading GeoLite2-Country...
2025-10-26 23:25:43,408 - configstream.geoip - ERROR - [geoip.py:54] - Failed to download GeoLite2-Country: Download failed
2025-10-26 23:25:43,410 - configstream.geoip - INFO - [geoip.py:49] - Downloading GeoLite2-City...
2025-10-26 23:25:43,412 - configstream.geoip - ERROR - [geoip.py:54] - Failed to download GeoLite2-City: Download failed
2025-10-26 23:25:43,584 - configstream.intelligent_fallback - INFO - [intelligent_fallback.py:62] - Saved 10 proxies for fallback use
2025-10-26 23:25:43,679 - configstream.intelligent_fallback - INFO - [intelligent_fallback.py:62] - Saved 600 proxies for fallback use
2025-10-26 23:25:43,687 - configstream.intelligent_fallback - WARNING - [intelligent_fallback.py:40] - No proxies to save for fallback
2025-10-26 23:25:43,694 - configstream.intelligent_fallback - INFO - [intelligent_fallback.py:62] - Saved 10 proxies for fallback use
2025-10-26 23:25:43,696 - configstream.intelligent_fallback - INFO - [intelligent_fallback.py:92] - Loaded 10 fallback proxies from 2025-10-26T23:25:43.692663+00:00
2025-10-26 23:25:43,701 - configstream.intelligent_fallback - WARNING - [intelligent_fallback.py:72] - No fallback data available
2025-10-26 23:25:43,707 - configstream.intelligent_fallback - ERROR - [intelligent_fallback.py:100] - Failed to load fallback data: Expecting property name enclosed in double quotes: line 1 column 3 (char 2)
2025-10-26 23:25:43,714 - configstream.intelligent_fallback - INFO - [intelligent_fallback.py:92] - Loaded 1 fallback proxies from 2025-10-23T00:00:00Z
2025-10-26 23:25:43,726 - configstream.intelligent_fallback - INFO - [intelligent_fallback.py:62] - Saved 1 proxies for fallback use
2025-10-26 23:25:43,728 - configstream.intelligent_fallback - INFO - [intelligent_fallback.py:92] - Loaded 1 fallback proxies from 2025-10-26T23:25:43.726137+00:00
2025-10-26 23:25:43,801 - configstream.parsers - WARNING - [parsers.py:40] - Invalid base64 characters: {'-'}
2025-10-26 23:25:43,806 - configstream.parsers - WARNING - [parsers.py:40] - Invalid base64 characters: {'-'}
2025-10-26 23:25:43,808 - configstream.parsers - WARNING - [parsers.py:40] - Invalid base64 characters: {'-'}
2025-10-26 23:25:43,846 - configstream.parsers - WARNING - [parsers.py:26] - Expected string, got NoneType
2025-10-26 23:25:44,204 - configstream.parsers - ERROR - [parsers.py:35] - Base64 input too large: 52428801 bytes (max: 52428800)
2025-10-26 23:25:44,211 - configstream.parsers - WARNING - [parsers.py:40] - Invalid base64 characters: {'&', '(', '@', '!', ')', '$', '^', '%', '#', '*'}
2025-10-26 23:25:44,218 - configstream.parsers - WARNING - [parsers.py:40] - Invalid base64 characters: {'!'}
2025-10-26 23:25:44,235 - configstream.parsers - WARNING - [parsers.py:102] - Payload has 15000 lines, truncating to 10000
2025-10-26 23:25:44,342 - configstream.parsers - WARNING - [parsers.py:123] - VMess config too long: 20000 bytes
2025-10-26 23:25:44,348 - configstream.parsers - WARNING - [parsers.py:72] - Base64 decode failed: Invalid base64-encoded string: number of data characters (13) cannot be 1 more than a multiple of 4
2025-10-26 23:25:44,361 - configstream.parsers - WARNING - [parsers.py:40] - Invalid base64 characters: {'&', '(', '@', '!', ')', '$', '^', '%', '#', '*'}
2025-10-26 23:25:44,480 - configstream.parsers - ERROR - [parsers.py:35] - Base64 input too large: 62914560 bytes (max: 52428800)
2025-10-26 23:25:44,487 - configstream.parsers - WARNING - [parsers.py:26] - Expected string, got int
2025-10-26 23:25:44,531 - configstream.parsers - WARNING - [parsers.py:40] - Invalid base64 characters: {'@', '#', '!'}
2025-10-26 23:25:44,532 - configstream.parsers - WARNING - [parsers.py:40] - Invalid base64 characters: {'@', '#', '!'}
2025-10-26 23:25:44,615 - configstream.pipeline - WARNING - [pipeline.py:103] - Skipping invalid source '': Source is empty
2025-10-26 23:25:44,617 - configstream.pipeline - WARNING - [pipeline.py:103] - Skipping invalid source 'ftp://invalid.com': Unsupported URL scheme: ftp
2025-10-26 23:25:44,812 - configstream.proxy_history - INFO - [proxy_history.py:211] - Exported history visualization data to /tmp/pytest-of-jules/pytest-17/test_export_for_visualization0/viz.json
2025-10-26 23:25:44,819 - configstream.proxy_history - INFO - [proxy_history.py:211] - Exported history visualization data to /tmp/pytest-of-jules/pytest-17/test_export_skips_empty_entrie0/viz.json
2025-10-26 23:25:44,826 - configstream.proxy_history - INFO - [proxy_history.py:247] - Cleaned up history for 1 proxies
2025-10-26 23:25:46,044 - configstream.security_validator - WARNING - [security_validator.py:92] - Dangerous port detected: 21
2025-10-26 23:25:46,047 - configstream.security_validator - WARNING - [security_validator.py:92] - Dangerous port detected: 22
2025-10-26 23:25:46,048 - configstream.security_validator - WARNING - [security_validator.py:92] - Dangerous port detected: 23
2025-10-26 23:25:46,054 - configstream.security_validator - WARNING - [security_validator.py:110] - Suspicious address pattern: localhost
2025-10-26 23:25:46,056 - configstream.security_validator - WARNING - [security_validator.py:110] - Suspicious address pattern: 127.0.0.1
2025-10-26 23:25:46,057 - configstream.security_validator - WARNING - [security_validator.py:110] - Suspicious address pattern: 0.0.0.0
2025-10-26 23:25:46,061 - configstream.security_validator - WARNING - [security_validator.py:110] - Suspicious address pattern: 192.168.1.1
2025-10-26 23:25:46,063 - configstream.security_validator - WARNING - [security_validator.py:110] - Suspicious address pattern: 10.0.0.1
2025-10-26 23:25:46,064 - configstream.security_validator - WARNING - [security_validator.py:138] - Private IP range detected: 172.16.0.1
2025-10-26 23:25:46,065 - configstream.security_validator - WARNING - [security_validator.py:138] - Private IP range detected: 172.31.255.255
2025-10-26 23:25:46,067 - configstream.security_validator - WARNING - [security_validator.py:110] - Suspicious address pattern: 169.254.1.1
2025-10-26 23:25:46,073 - configstream.security_validator - WARNING - [security_validator.py:156] - Special address detected: ::1
2025-10-26 23:25:46,074 - configstream.security_validator - WARNING - [security_validator.py:156] - Special address detected: fe80::1
2025-10-26 23:25:46,076 - configstream.security_validator - WARNING - [security_validator.py:156] - Special address detected: fc00::1
2025-10-26 23:25:46,077 - configstream.security_validator - WARNING - [security_validator.py:156] - Special address detected: fd00::1
2025-10-26 23:25:46,081 - configstream.security_validator - WARNING - [security_validator.py:164] - Non-standard IP notation: 0x7f000001
2025-10-26 23:25:46,083 - configstream.security_validator - WARNING - [security_validator.py:164] - Non-standard IP notation: 0177.0.0.1
2025-10-26 23:25:46,094 - configstream.security_validator - ERROR - [security_validator.py:188] - Null byte detected in config
2025-10-26 23:25:46,097 - configstream.security_validator - ERROR - [security_validator.py:213] - Suspicious pattern detected: \$\(
2025-10-26 23:25:46,099 - configstream.security_validator - ERROR - [security_validator.py:213] - Suspicious pattern detected: ;\s*rm\s
2025-10-26 23:25:46,101 - configstream.security_validator - ERROR - [security_validator.py:213] - Suspicious pattern detected: &&\s*rm\s
2025-10-26 23:25:46,102 - configstream.security_validator - ERROR - [security_validator.py:213] - Suspicious pattern detected: \|\s*sh
2025-10-26 23:25:46,103 - configstream.security_validator - ERROR - [security_validator.py:213] - Suspicious pattern detected: `
2025-10-26 23:25:46,105 - configstream.security_validator - ERROR - [security_validator.py:213] - Suspicious pattern detected: eval\s*\(
2025-10-26 23:25:46,110 - configstream.security_validator - WARNING - [security_validator.py:221] - Config too long: 15008 chars
2025-10-26 23:25:46,124 - configstream.security_validator - WARNING - [security_validator.py:110] - Suspicious address pattern: localhost
2025-10-26 23:25:46,126 - configstream.security_validator - WARNING - [security_validator.py:110] - Suspicious address pattern: 127.0.0.1
2025-10-26 23:25:46,127 - configstream.security_validator - WARNING - [security_validator.py:110] - Suspicious address pattern: 0.0.0.0
2025-10-26 23:25:46,131 - configstream.security_validator - WARNING - [security_validator.py:110] - Suspicious address pattern: 192.168.1.1
2025-10-26 23:25:46,132 - configstream.security_validator - WARNING - [security_validator.py:110] - Suspicious address pattern: 10.0.0.1
2025-10-26 23:25:46,134 - configstream.security_validator - WARNING - [security_validator.py:138] - Private IP range detected: 172.16.0.1
2025-10-26 23:25:46,153 - configstream.security_validator - WARNING - [security_validator.py:92] - Dangerous port detected: 22
2025-10-26 23:25:46,155 - configstream.security_validator - WARNING - [security_validator.py:110] - Suspicious address pattern: localhost
2025-10-26 23:25:46,156 - configstream.security_validator - WARNING - [security_validator.py:370] - Insecure proxy filtered: localhost:22
2025-10-26 23:25:46,157 - configstream.security_validator - INFO - [security_validator.py:378] - Security validation: 2/3 proxies passed
2025-10-26 23:25:46,161 - configstream.security_validator - WARNING - [security_validator.py:110] - Suspicious address pattern: 127.0.0.1
2025-10-26 23:25:46,162 - configstream.security_validator - WARNING - [security_validator.py:370] - Insecure proxy filtered: 127.0.0.1:443
2025-10-26 23:25:46,164 - configstream.security_validator - INFO - [security_validator.py:378] - Security validation: 0/1 proxies passed
2025-10-26 23:25:46,167 - configstream.security_validator - INFO - [security_validator.py:378] - Security validation: 1/1 proxies passed
2025-10-26 23:25:46,171 - configstream.security_validator - INFO - [security_validator.py:378] - Security validation: 0/0 proxies passed
2025-10-26 23:25:46,174 - configstream.security_validator - WARNING - [security_validator.py:92] - Dangerous port detected: 22
2025-10-26 23:25:46,176 - configstream.security_validator - WARNING - [security_validator.py:110] - Suspicious address pattern: localhost
2025-10-26 23:25:46,177 - configstream.security_validator - WARNING - [security_validator.py:370] - Insecure proxy filtered: localhost:22
2025-10-26 23:25:46,178 - configstream.security_validator - WARNING - [security_validator.py:92] - Dangerous port detected: 23
2025-10-26 23:25:46,180 - configstream.security_validator - WARNING - [security_validator.py:110] - Suspicious address pattern: 127.0.0.1
2025-10-26 23:25:46,181 - configstream.security_validator - WARNING - [security_validator.py:370] - Insecure proxy filtered: 127.0.0.1:23
2025-10-26 23:25:46,182 - configstream.security_validator - INFO - [security_validator.py:378] - Security validation: 0/2 proxies passed
2025-10-26 23:25:46,336 - configstream.test_cache - INFO - [test_cache.py:71] - Test cache initialized at /tmp/tmpafvr6c_l/test.db with WAL mode
2025-10-26 23:25:46,347 - configstream.test_cache - INFO - [test_cache.py:71] - Test cache initialized at /tmp/tmpenw7wsv1/test.db with WAL mode
2025-10-26 23:25:46,361 - configstream.test_cache - INFO - [test_cache.py:71] - Test cache initialized at /tmp/tmpucqn1tej/test.db with WAL mode
2025-10-26 23:25:46,366 - configstream.test_cache - INFO - [test_cache.py:71] - Test cache initialized at /tmp/tmpucqn1tej/test.db with WAL mode
2025-10-26 23:25:46,376 - configstream.test_cache - INFO - [test_cache.py:71] - Test cache initialized at /tmp/tmp2a88epfh/test.db with WAL mode
2025-10-26 23:25:46,379 - configstream.test_cache - INFO - [test_cache.py:71] - Test cache initialized at /tmp/tmp2a88epfh/test.db with WAL mode
2025-10-26 23:25:46,390 - configstream.test_cache - INFO - [test_cache.py:71] - Test cache initialized at /tmp/tmp49bnh9fc/test.db with WAL mode
2025-10-26 23:25:46,405 - configstream.test_cache - INFO - [test_cache.py:71] - Test cache initialized at /tmp/tmpxegjz5bg/test.db with WAL mode
2025-10-26 23:25:46,419 - configstream.test_cache - INFO - [test_cache.py:71] - Test cache initialized at /tmp/tmproogr7e9/test.db with WAL mode
2025-10-26 23:25:46,422 - configstream.test_cache - INFO - [test_cache.py:71] - Test cache initialized at /tmp/tmproogr7e9/test.db with WAL mode
2025-10-26 23:25:46,428 - configstream.test_cache - INFO - [test_cache.py:243] - Cleaned up 1 expired cache entries
2025-10-26 23:25:46,438 - configstream.test_cache - INFO - [test_cache.py:71] - Test cache initialized at /tmp/tmpq16yj_yl/test.db with WAL mode
2025-10-26 23:25:46,458 - configstream.testers - ERROR - [testers.py:293] - Proxy test error for vmess://config: Connection error
2025-10-26 23:25:46,467 - configstream.testers - ERROR - [testers.py:293] - Proxy test error for vmess://config: Connection error
2025-10-26 23:25:59,550 - configstream.test_cache - INFO - [test_cache.py:71] - Test cache initialized at /tmp/tmpcdu_yh0f/test.db with WAL mode
